Current working directory
/zfs/projects/darc/wolee_edehaan_suzienoh-exploratory-ml/kevin
source venv/bin/activate
which python3
/zfs/projects/darc/wolee_edehaan_suzienoh-exploratory-ml/kevin/venv/bin/python3
Intel(R) Extension for Scikit-learn* enabled (https://github.com/intel/scikit-learn-intelex)
Intel(R) Extension for Scikit-learn* enabled (https://github.com/intel/scikit-learn-intelex)
INFO:preprocess_data_nn.py:

Loading and preprocessing data...

DEBUG:preprocess_data_nn.py:      date  permno
0  1980-01   10006
1  1980-01   10057
2  1980-01   10103
3  1980-01   10137
4  1980-01   10145
DEBUG:preprocess_data_nn.py:--------------------------------------------------
INFO:main.py:preprocessed df: (2216189, 158)
INFO:preprocess_data_nn.py:

Applying secondary data preprocessing..

INFO:main.py:secondary preprocessed df: (2165515, 158)
INFO:main.py:df sample:    permno  gvkey   adatadate  fyear  sic2     spi       mve_f  ...     zerotrade      beta    betasq      rsq1  pricedelay   idiovol  pyear
0   10006   1010  12/31/1978   1978    37  0.0000  269.308500  ...  1.115306e-07  1.060420  1.124491  0.343408    0.029859  0.025576   1980
1   10057   1098  09/30/1978   1978    36  0.0000   97.372000  ...  6.199128e-08  1.526013  2.328716  0.307905    0.092667  0.037473   1980
2   10103   1012  10/31/1978   1978    33     NaN    1.697500  ...           NaN  1.759493  3.095816  0.096753    0.221851  0.087020   1980
3   10137   1279  12/31/1978   1978    49     NaN  537.524500  ...  9.726790e-08  0.492885  0.242936  0.189693    0.125777  0.017540   1980
4   10145   1300  12/31/1978   1978    99 -0.0031  805.633282  ...  6.190654e-08  1.139163  1.297691  0.279437    0.024228  0.031201   1980

[5 rows x 158 columns]
INFO:main.py:

Transform data

INFO:transform_data_nn.py:Train data years: [1980, 1981, 1982, 1983, 1984, 1985, 1986]
INFO:transform_data_nn.py:Train_data: (341783, 158)

INFO:transform_data_nn.py:Test data years: [1987]
INFO:transform_data_nn.py:Test_data: (53899, 158)

INFO:transform_data_nn.py:Retrain data years: [1980, 1981, 1982, 1983, 1984, 1985, 1986, 1987]
INFO:transform_data_nn.py:Retrain_data: (395682, 158)

INFO:transform_data_nn.py:Prediction data years: [1988]
INFO:transform_data_nn.py:Prediction_data: (56005, 158)

DEBUG:main.py:Pipeline built: Pipeline(steps=[('Time_period_mean_imputation',
                 _TimePeriodMeanTransformer(date_column='date',
                                            numeric_columns=['absacc', 'acc',
                                                             'aeavol', 'age',
                                                             'agr', 'baspread',
                                                             'beta', 'betasq',
                                                             'bm', 'bm_ia',
                                                             'cash', 'cashdebt',
                                                             'cashpr', 'cfp',
                                                             'cfp_ia',
                                                             'chatoia',
                                                             'chcsho',
                                                             'chempia',
                                                             'chfeps', 'chinv',
                                                             'chmom',
                                                             'chnanalyst',
                                                             'chpmia', 'chtx',
                                                             'cinvest',
                                                             'currat', 'depr',
                                                             'disp', 'dolvo...
                                                   'chempia', 'chfeps', 'chinv',
                                                   'chmom', 'chnanalyst',
                                                   'chpmia', 'chtx', 'cinvest',
                                                   'currat', 'depr', 'disp',
                                                   'dolvol', 'dy', ...]),
                                                 ('cat',
                                                  Pipeline(steps=[('impute_cat',
                                                                   SimpleImputer(fill_value=0,
                                                                                 strategy='constant'))]),
                                                  ['convind', 'divi', 'divo',
                                                   'ipo', 'rd', 'securedind',
                                                   'sin']),
                                                 ('embed',
                                                  Pipeline(steps=[('impute_embed',
                                                                   SimpleImputer(fill_value=0,
                                                                                 strategy='constant'))]),
                                                  ['permno'])]))])
INFO:main.py:

Generate X and y with train_data and test_data

DEBUG:main.py:Save the reload the tensors for much faster debugging
INFO:main.py:Tensors directory already exists at: /zfs/projects/darc/wolee_edehaan_suzienoh-exploratory-ml/kevin/tensors
DEBUG:main.py:Load the tensors
INFO:main.py:
        x_train_tf: torch.Size([341783, 103])
        y_train_tf: torch.Size([341783])

        x_test_tf: torch.Size([53899, 103])
        y_test_tf: torch.Size([53899])

    
INFO:main.py:
        x_retrain_tf: torch.Size([395682, 103])
        y_retrain_tf: torch.Size([395682])

        x_prediction_tf: torch.Size([56005, 103])
        y_prediction_tf: torch.Size([56005])

    
INFO:main.py:Create train_dataset
INFO:main.py:train_dataset first example: (tensor([ 0.2614,  0.5034,  0.2386, -0.6303,  0.0469, -0.5241, -0.0284, -0.2584,
         0.3866,  0.1910, -0.8830,  0.0062, -0.5088, -0.1862, -0.0053,  0.0250,
        -0.4235,  0.1175,  0.0000,  0.6719, -0.3586,  0.0000,  0.0257,  0.0166,
         0.0370, -0.2229, -0.6756,  0.0000,  0.5764,  1.1873,  0.6227, -0.1414,
         0.5064,  0.0000, -0.5226, -0.2165,  0.1496,  0.1907,  0.1020, -1.1512,
        -0.3211,  0.0239,  0.3191, -0.0440, -0.0208, -0.6509, -0.0216, -0.0993,
        -0.6609, -0.2278, -0.1547,  0.9190, -0.1748,  0.0000,  0.0265, -0.3809,
        -0.9466, -0.0875, -0.6362, -0.1616,  0.1008, -0.6415, -0.3684, -0.1993,
        -0.2698, -0.5237,  0.0996, -0.1018, -0.1900, -0.4132, -0.7240, -0.3249,
         0.0346, -0.8136,  0.1052, -1.0783,  0.2870,  0.2369,  0.6056,  0.1760,
        -0.4392, -0.2020, -0.0110,  0.0000, -0.0826, -0.0538, -0.3134, -0.6841,
        -0.4092, -0.4207,  0.1949, -0.2766,  0.1496, -0.1756, -0.5206,  0.0000,
         0.0000,  0.0000,  0.0000,  0.0000,  0.0000,  0.0000]), tensor([4658]), tensor(0.2117))
INFO:main.py:Create test_dataset
INFO:main.py:test_dataset first example: (tensor([-6.9920e-03,  8.9557e-03, -3.4033e-01, -1.6683e+00,  4.0069e-03,
         1.0097e+00, -2.5891e-03, -1.0957e-02, -9.5448e-01,  1.8591e-01,
         3.8505e-01,  6.2086e-01,  1.9972e-01,  2.1500e-02, -2.2037e-05,
         6.4081e-03, -7.8682e-03,  1.2509e-02,  0.0000e+00,  2.2175e-02,
        -7.5173e-02,  0.0000e+00, -1.5533e-02,  1.2460e-02,  3.1036e-02,
         1.3005e-01, -2.3377e-01,  0.0000e+00, -4.6695e-01, -7.7328e-01,
        -6.6426e-01,  6.0568e-03, -1.6879e-02,  0.0000e+00,  1.5509e-02,
        -1.9876e-03,  9.2778e-03, -4.6920e-01,  6.8878e-04, -2.7767e-02,
        -1.1036e-01, -6.2118e-01,  1.3711e-02, -4.6129e-01, -4.5306e-03,
         2.2998e+00,  1.6293e-02, -1.3041e+00,  5.4224e-02, -1.1150e-03,
        -8.5550e-01, -1.1288e+00, -3.1813e-01,  0.0000e+00, -8.7597e-01,
         1.4499e-02,  3.0605e-02,  1.3658e-02, -8.7689e-03, -1.7061e-02,
         1.2506e-02, -1.1364e-02, -2.6022e-03,  1.5424e-03, -6.5274e-04,
        -7.4535e-03, -6.8802e-03, -2.2825e-02,  2.5533e-02,  1.5004e-01,
        -1.1726e-02, -2.4365e-02,  3.4575e-02,  1.6018e+00, -3.4779e+00,
        -7.2764e-02, -2.0625e+00,  4.1949e-01, -3.2436e-01, -4.6815e-01,
        -4.0800e-01, -3.1863e-01,  1.6746e+00,  0.0000e+00, -3.2632e-03,
        -6.4726e-01,  8.8510e-02,  5.2651e-01, -4.4860e-02, -4.4852e-02,
        -2.1688e-01,  1.4353e+00,  1.8772e-01,  3.0461e-01, -5.2065e-01,
         0.0000e+00,  0.0000e+00,  0.0000e+00,  1.0000e+00,  0.0000e+00,
         1.0000e+00,  0.0000e+00]), tensor([3315]), tensor(-0.5200))
INFO:main.py:Create retrain_dataset
INFO:main.py:retrain_dataset first example: (tensor([ 2.4375e-01,  4.9617e-01,  2.3474e-01, -6.5108e-01,  3.9445e-02,
        -5.2971e-01, -3.2399e-02, -2.6454e-01,  4.4939e-01,  1.9404e-01,
        -8.7559e-01,  2.9982e-02, -5.1678e-01, -1.7870e-01,  2.8057e-02,
         2.6105e-02, -4.2786e-01,  1.3802e-01,  0.0000e+00,  6.8093e-01,
        -3.5624e-01,  0.0000e+00,  3.2302e-02, -4.2100e-03,  2.3124e-02,
        -2.2767e-01, -6.6230e-01,  0.0000e+00,  5.4395e-01,  1.2575e+00,
         6.0546e-01, -1.2386e-01,  5.1282e-01,  0.0000e+00, -5.0374e-01,
        -2.0934e-01,  1.6390e-01,  1.9552e-01,  8.7618e-02, -1.1469e+00,
        -3.1720e-01,  6.2132e-02,  3.3133e-01, -2.5122e-02, -3.4593e-02,
        -6.5851e-01,  4.2816e-04, -7.2423e-02, -6.5629e-01, -2.1883e-01,
        -1.4935e-01,  8.9773e-01, -1.5623e-01,  0.0000e+00,  2.4546e-02,
        -3.5709e-01, -9.4222e-01, -1.1718e-01, -6.1813e-01, -1.7652e-01,
         1.0460e-01, -6.2822e-01, -3.6749e-01, -1.8878e-01, -2.6630e-01,
        -5.2445e-01,  7.6502e-02, -1.0615e-01, -1.6425e-01, -4.0413e-01,
        -7.2657e-01, -3.3089e-01,  3.7161e-02, -8.1525e-01,  1.3346e-01,
        -9.9192e-01,  2.9311e-01,  2.4566e-01,  6.3414e-01,  1.7033e-01,
        -4.4184e-01, -2.0106e-01, -3.8979e-03,  0.0000e+00, -7.9384e-02,
        -1.3757e-02, -3.2263e-01, -6.8126e-01, -1.6517e-01, -1.5155e-01,
         1.8087e-01, -2.6300e-01,  1.4201e-01, -2.0741e-01, -5.1845e-01,
         0.0000e+00,  0.0000e+00,  0.0000e+00,  0.0000e+00,  0.0000e+00,
         0.0000e+00,  0.0000e+00]), tensor([5107]), tensor(0.2117))
INFO:main.py:Create prediction_dataset
INFO:main.py:prediction_dataset first example: (tensor([-9.6036e-01, -4.9283e-01, -4.7202e-01, -1.2875e+00, -5.9088e-01,
        -3.4143e-01, -1.7353e+00, -1.0156e+00,  6.0711e-02,  1.9547e-01,
        -4.0377e-01, -9.2351e-03, -4.1386e-03, -3.5552e-02,  1.6291e-02,
         4.4557e-03, -4.1867e-01,  1.1388e-02,  0.0000e+00, -2.8223e-01,
        -1.5983e-01,  0.0000e+00,  8.3143e-02,  4.9025e-02, -1.0656e-02,
        -6.2313e-01, -8.2264e-01,  0.0000e+00, -5.7750e-01,  1.3797e+00,
        -1.6007e+00, -3.2115e-01,  1.1211e-01,  0.0000e+00, -1.0634e+00,
         3.8040e-03, -5.2228e-01, -8.2825e-01, -2.7243e-01, -8.6950e-01,
         5.3128e-01, -8.5044e-01, -3.8617e-01, -2.6063e-01, -4.5432e-01,
        -1.9406e-01,  1.0492e-02, -3.0692e-01,  5.1011e-03, -9.7349e-03,
        -8.4332e-01, -1.1018e+00, -1.1294e+00,  0.0000e+00, -8.6923e-01,
        -9.1403e-01,  2.6640e-02, -1.2260e-01, -3.3319e-01, -3.9018e-02,
        -1.9560e-01, -3.4380e-01, -1.7398e-01,  3.2079e-01, -1.7674e-03,
        -4.6619e-01, -2.1413e-01,  1.4636e+00, -8.8986e-01, -3.8259e-01,
        -9.5638e-03, -3.3089e-02,  3.7161e-02,  3.0098e-02, -4.4583e-01,
        -7.1099e-02, -3.4420e-01,  8.4362e-02, -6.3088e-01, -2.8029e-01,
         4.2441e+00,  3.3876e-01, -3.8979e-03,  0.0000e+00, -7.6692e-01,
        -6.3231e-02,  2.3258e+00,  5.0224e+00, -3.6348e-02, -4.6659e-02,
         2.0041e-01, -8.0320e-01, -4.0666e-01,  3.0623e-01,  1.1257e+00,
         0.0000e+00,  0.0000e+00,  0.0000e+00,  0.0000e+00,  0.0000e+00,
         0.0000e+00,  0.0000e+00]), tensor([743]), tensor(0.0638))
INFO:main.py:train and test dataloader
INFO:main.py:train_loader first example: [tensor([[-1.0088e+00, -5.4216e-01, -4.3827e-01,  ...,  0.0000e+00,
          0.0000e+00,  0.0000e+00],
        [-6.9240e-01, -2.8173e-01, -2.2381e-03,  ...,  0.0000e+00,
          0.0000e+00,  0.0000e+00],
        [-2.1133e-01,  1.1428e-01, -3.3944e-01,  ...,  0.0000e+00,
          0.0000e+00,  0.0000e+00],
        ...,
        [ 4.2181e+00,  3.3445e+00, -9.9015e-01,  ...,  1.0000e+00,
          1.0000e+00,  0.0000e+00],
        [-2.6579e-01,  6.9446e-02,  2.2379e-01,  ...,  0.0000e+00,
          0.0000e+00,  0.0000e+00],
        [-5.0509e-01, -1.2754e-01, -3.0765e-01,  ...,  1.0000e+00,
          1.0000e+00,  0.0000e+00]]), tensor([[ 744],
        [6406],
        [4041],
        [5012],
        [3544],
        [4236],
        [6607],
        [4539],
        [5727],
        [3836],
        [3768],
        [3586],
        [1462],
        [4370],
        [5168],
        [2264],
        [5308],
        [2104],
        [1272],
        [2800],
        [3804],
        [1771],
        [5532],
        [5696],
        [2918],
        [2102],
        [4159],
        [4624],
        [5925],
        [ 922],
        [3846],
        [2478]]), tensor([ 0.0655, -0.0700,  0.0394,  0.0787,  0.1803, -0.0815, -0.2308,  0.0750,
         0.0774,  0.0566,  0.1026,  0.0150, -0.0853, -0.0414,  0.0484,  0.0000,
         0.1579,  0.1905,  0.0409, -0.0023, -0.0377,  0.3750, -0.0077,  0.0000,
         0.0371,  0.0653,  0.2111,  0.0000, -0.1364,  0.0000, -0.0100,  0.1071])]

INFO:main.py:test_loader first example: [tensor([[-6.9920e-03,  8.9557e-03, -3.4033e-01,  ...,  0.0000e+00,
          1.0000e+00,  0.0000e+00],
        [-6.9920e-03,  8.9557e-03, -6.7673e-04,  ...,  0.0000e+00,
          0.0000e+00,  0.0000e+00],
        [-6.9920e-03,  8.9557e-03,  1.0606e-01,  ...,  0.0000e+00,
          0.0000e+00,  0.0000e+00],
        ...,
        [-3.9113e-01, -3.3732e-02, -8.1276e-01,  ...,  0.0000e+00,
          1.0000e+00,  1.0000e+00],
        [-9.6154e-01, -5.0328e-01, -6.0189e-01,  ...,  0.0000e+00,
          0.0000e+00,  0.0000e+00],
        [ 3.6633e+00,  3.3038e+00,  1.8561e+00,  ...,  0.0000e+00,
          0.0000e+00,  0.0000e+00]]), tensor([[3315],
        [2425],
        [1247],
        [3335],
        [ 932],
        [ 496],
        [ 596],
        [1865],
        [ 148],
        [ 107],
        [1118],
        [  91],
        [3151],
        [ 688],
        [ 138],
        [1802],
        [2698],
        [4661],
        [2867],
        [4254],
        [1152],
        [1012],
        [2176],
        [ 535],
        [4450],
        [3869],
        [2930],
        [ 385],
        [2748],
        [1881],
        [2031],
        [2570]]), tensor([-0.5200,  0.0000, -0.0217,  0.0909,  0.0417, -0.2105,  0.1136,  0.3243,
         0.0667,  0.2500,  0.1060,  0.1562,  0.4306,  0.1304, -0.0133, -0.0222,
        -0.2667, -0.1571,  0.1707,  0.0667,  0.0847,  0.1776,  0.2695,  0.0476,
         0.1163,  0.2268, -0.1351,  0.0000,  0.3103,  0.1769,  0.1379,  0.2647])]

INFO:main.py:retrain and prediction dataloader
INFO:main.py:retrain_loader first example: [tensor([[-6.4251e-01, -2.3176e-01, -1.2428e-02,  ...,  0.0000e+00,
          1.0000e+00,  0.0000e+00],
        [ 6.6112e-03, -8.9386e-04,  1.0027e-01,  ...,  0.0000e+00,
          1.0000e+00,  0.0000e+00],
        [-1.1822e+00, -7.7625e-01,  4.7390e-02,  ...,  0.0000e+00,
          1.0000e+00,  0.0000e+00],
        ...,
        [ 1.7761e+00,  1.7547e+00,  7.9389e-03,  ...,  0.0000e+00,
          0.0000e+00,  0.0000e+00],
        [-4.8290e-01, -1.0067e-01,  1.6989e+00,  ...,  0.0000e+00,
          1.0000e+00,  0.0000e+00],
        [ 5.6217e-03, -3.3511e-03, -8.8565e-01,  ...,  0.0000e+00,
          0.0000e+00,  0.0000e+00]]), tensor([[4569],
        [  84],
        [4955],
        [1890],
        [ 402],
        [  16],
        [4092],
        [4858],
        [ 634],
        [ 671],
        [6155],
        [4961],
        [1739],
        [6747],
        [3727],
        [2826],
        [3058],
        [2447],
        [5003],
        [ 187],
        [3564],
        [3393],
        [6584],
        [ 745],
        [4290],
        [5363],
        [2200],
        [2043],
        [1202],
        [3936],
        [6561],
        [3205]]), tensor([-0.0385,  0.0476, -0.1154,  0.0000,  0.3143,  0.3333,  0.2000,  0.1145,
         0.1567,  0.1346,  0.0615, -0.1176,  0.1224, -0.0654,  0.1617,  0.0000,
         0.0312,  0.0342, -0.0789,  0.3538,  0.1223,  0.0124,  0.1680,  0.0000,
         0.1739, -0.0413, -0.0680,  0.0992,  0.0638, -0.1042,  0.0435,  0.0425])]

INFO:main.py:prediction_loader first example: [tensor([[-0.9604, -0.4928, -0.4720,  ...,  0.0000,  0.0000,  0.0000],
        [-0.0053,  0.0067,  3.1135,  ...,  0.0000,  0.0000,  0.0000],
        [-0.0053,  0.0067, -0.1770,  ...,  0.0000,  1.0000,  0.0000],
        ...,
        [ 0.0554,  0.3415, -0.3227,  ...,  0.0000,  1.0000,  0.0000],
        [-0.0053,  0.0067, -0.3629,  ...,  0.0000,  1.0000,  0.0000],
        [-0.0053,  0.0067,  1.4540,  ...,  0.0000,  1.0000,  0.0000]]), tensor([[ 743],
        [3829],
        [4020],
        [1448],
        [3463],
        [ 474],
        [1251],
        [1075],
        [2604],
        [1828],
        [1750],
        [1310],
        [3224],
        [2001],
        [3481],
        [2706],
        [ 612],
        [ 974],
        [1443],
        [ 430],
        [4586],
        [3357],
        [1247],
        [ 527],
        [3280],
        [ 626],
        [1951],
        [ 502],
        [3744],
        [ 156],
        [3261],
        [4985]]), tensor([ 0.0638,  0.1111,  0.1190, -0.0606,  0.0769,  0.0467, -0.0147, -0.1111,
        -0.0345,  0.0000, -0.1304, -0.0476,  0.0682,  0.0517,  0.2500, -0.1176,
        -0.0357,  0.0000,  0.2500,  0.2075, -0.3333,  0.0000, -0.0909, -0.3077,
         0.1212, -0.0556,  0.2353, -0.1923, -0.0952, -0.0845,  0.6875,  0.0800])]

INFO:main.py:Hyperparameters tuning with Ray Tune
INFO:main.py:Training data years: [1980, 1981, 1982, 1983, 1984, 1985, 1986]
INFO:main.py:Testing data year: 1987
2024-07-02 22:54:43,898	INFO worker.py:1753 -- Started a local Ray instance.
2024-07-02 22:54:43,926	INFO packaging.py:530 -- Creating a file package for local directory '/zfs/projects/darc/wolee_edehaan_suzienoh-exploratory-ml/kevin/src'.
2024-07-02 22:54:43,951	INFO packaging.py:358 -- Pushing file package 'gcs://_ray_pkg_355028f0108691b8.zip' (1.19MiB) to Ray cluster...
2024-07-02 22:54:43,960	INFO packaging.py:371 -- Successfully pushed file package 'gcs://_ray_pkg_355028f0108691b8.zip'.
2024-07-02 22:54:45,911	WARNING tune.py:902 -- AIR_VERBOSITY is set, ignoring passed-in ProgressReporter for now.
2024-07-02 22:54:54,006	ERROR tune_controller.py:1331 -- Trial task failed for trial train_fnn_13ce7_00001
Traceback (most recent call last):
  File "/zfs/projects/darc/wolee_edehaan_suzienoh-exploratory-ml/kevin/venv/lib/python3.10/site-packages/ray/air/execution/_internal/event_manager.py", line 110, in resolve_future
    result = ray.get(future)
  File "/zfs/projects/darc/wolee_edehaan_suzienoh-exploratory-ml/kevin/venv/lib/python3.10/site-packages/ray/_private/auto_init_hook.py", line 21, in auto_init_wrapper
    return fn(*args, **kwargs)
  File "/zfs/projects/darc/wolee_edehaan_suzienoh-exploratory-ml/kevin/venv/lib/python3.10/site-packages/ray/_private/client_mode_hook.py", line 103, in wrapper
    return func(*args, **kwargs)
  File "/zfs/projects/darc/wolee_edehaan_suzienoh-exploratory-ml/kevin/venv/lib/python3.10/site-packages/ray/_private/worker.py", line 2613, in get
    values, debugger_breakpoint = worker.get_objects(object_refs, timeout=timeout)
  File "/zfs/projects/darc/wolee_edehaan_suzienoh-exploratory-ml/kevin/venv/lib/python3.10/site-packages/ray/_private/worker.py", line 861, in get_objects
    raise value.as_instanceof_cause()
ray.exceptions.RayTaskError(AttributeError): [36mray::ImplicitFunc.train()[39m (pid=3489640, ip=10.112.2.40, actor_id=e71fe2de039bfbea3b0e94b101000000, repr=train_fnn)
  File "/zfs/projects/darc/wolee_edehaan_suzienoh-exploratory-ml/kevin/venv/lib/python3.10/site-packages/ray/tune/trainable/trainable.py", line 331, in train
    raise skipped from exception_cause(skipped)
  File "/zfs/projects/darc/wolee_edehaan_suzienoh-exploratory-ml/kevin/venv/lib/python3.10/site-packages/ray/air/_internal/util.py", line 98, in run
    self._ret = self._target(*self._args, **self._kwargs)
  File "/zfs/projects/darc/wolee_edehaan_suzienoh-exploratory-ml/kevin/venv/lib/python3.10/site-packages/ray/tune/trainable/function_trainable.py", line 45, in <lambda>
    training_func=lambda: self._trainable_func(self.config),
  File "/zfs/projects/darc/wolee_edehaan_suzienoh-exploratory-ml/kevin/venv/lib/python3.10/site-packages/ray/tune/trainable/function_trainable.py", line 248, in _trainable_func
    output = fn()
  File "/zfs/projects/darc/wolee_edehaan_suzienoh-exploratory-ml/kevin/venv/lib/python3.10/site-packages/ray/tune/trainable/util.py", line 130, in inner
    return trainable(config, **fn_kwargs)
  File "/tmp/ray/session_2024-07-02_22-54-41_444445_3481399/runtime_resources/working_dir_files/_ray_pkg_355028f0108691b8/model_data_nn.py", line 159, in train_fnn
    loss_function = nn.MSE
AttributeError: module 'torch.nn' has no attribute 'MSE'
2024-07-02 22:54:54,016	ERROR tune_controller.py:1331 -- Trial task failed for trial train_fnn_13ce7_00000
Traceback (most recent call last):
  File "/zfs/projects/darc/wolee_edehaan_suzienoh-exploratory-ml/kevin/venv/lib/python3.10/site-packages/ray/air/execution/_internal/event_manager.py", line 110, in resolve_future
    result = ray.get(future)
  File "/zfs/projects/darc/wolee_edehaan_suzienoh-exploratory-ml/kevin/venv/lib/python3.10/site-packages/ray/_private/auto_init_hook.py", line 21, in auto_init_wrapper
    return fn(*args, **kwargs)
  File "/zfs/projects/darc/wolee_edehaan_suzienoh-exploratory-ml/kevin/venv/lib/python3.10/site-packages/ray/_private/client_mode_hook.py", line 103, in wrapper
    return func(*args, **kwargs)
  File "/zfs/projects/darc/wolee_edehaan_suzienoh-exploratory-ml/kevin/venv/lib/python3.10/site-packages/ray/_private/worker.py", line 2613, in get
    values, debugger_breakpoint = worker.get_objects(object_refs, timeout=timeout)
  File "/zfs/projects/darc/wolee_edehaan_suzienoh-exploratory-ml/kevin/venv/lib/python3.10/site-packages/ray/_private/worker.py", line 861, in get_objects
    raise value.as_instanceof_cause()
ray.exceptions.RayTaskError(AttributeError): [36mray::ImplicitFunc.train()[39m (pid=3489639, ip=10.112.2.40, actor_id=6196c3a597afc6c1be513c2501000000, repr=train_fnn)
  File "/zfs/projects/darc/wolee_edehaan_suzienoh-exploratory-ml/kevin/venv/lib/python3.10/site-packages/ray/tune/trainable/trainable.py", line 331, in train
    raise skipped from exception_cause(skipped)
  File "/zfs/projects/darc/wolee_edehaan_suzienoh-exploratory-ml/kevin/venv/lib/python3.10/site-packages/ray/air/_internal/util.py", line 98, in run
    self._ret = self._target(*self._args, **self._kwargs)
  File "/zfs/projects/darc/wolee_edehaan_suzienoh-exploratory-ml/kevin/venv/lib/python3.10/site-packages/ray/tune/trainable/function_trainable.py", line 45, in <lambda>
    training_func=lambda: self._trainable_func(self.config),
  File "/zfs/projects/darc/wolee_edehaan_suzienoh-exploratory-ml/kevin/venv/lib/python3.10/site-packages/ray/tune/trainable/function_trainable.py", line 248, in _trainable_func
    output = fn()
  File "/zfs/projects/darc/wolee_edehaan_suzienoh-exploratory-ml/kevin/venv/lib/python3.10/site-packages/ray/tune/trainable/util.py", line 130, in inner
    return trainable(config, **fn_kwargs)
  File "/tmp/ray/session_2024-07-02_22-54-41_444445_3481399/runtime_resources/working_dir_files/_ray_pkg_355028f0108691b8/model_data_nn.py", line 159, in train_fnn
    loss_function = nn.MSE
AttributeError: module 'torch.nn' has no attribute 'MSE'
2024-07-02 22:54:59,714	ERROR tune_controller.py:1331 -- Trial task failed for trial train_fnn_13ce7_00002
Traceback (most recent call last):
  File "/zfs/projects/darc/wolee_edehaan_suzienoh-exploratory-ml/kevin/venv/lib/python3.10/site-packages/ray/air/execution/_internal/event_manager.py", line 110, in resolve_future
    result = ray.get(future)
  File "/zfs/projects/darc/wolee_edehaan_suzienoh-exploratory-ml/kevin/venv/lib/python3.10/site-packages/ray/_private/auto_init_hook.py", line 21, in auto_init_wrapper
    return fn(*args, **kwargs)
  File "/zfs/projects/darc/wolee_edehaan_suzienoh-exploratory-ml/kevin/venv/lib/python3.10/site-packages/ray/_private/client_mode_hook.py", line 103, in wrapper
    return func(*args, **kwargs)
  File "/zfs/projects/darc/wolee_edehaan_suzienoh-exploratory-ml/kevin/venv/lib/python3.10/site-packages/ray/_private/worker.py", line 2613, in get
    values, debugger_breakpoint = worker.get_objects(object_refs, timeout=timeout)
  File "/zfs/projects/darc/wolee_edehaan_suzienoh-exploratory-ml/kevin/venv/lib/python3.10/site-packages/ray/_private/worker.py", line 861, in get_objects
    raise value.as_instanceof_cause()
ray.exceptions.RayTaskError(AttributeError): [36mray::ImplicitFunc.train()[39m (pid=3489876, ip=10.112.2.40, actor_id=56ce4668d5581b2939c2b8c601000000, repr=train_fnn)
  File "/zfs/projects/darc/wolee_edehaan_suzienoh-exploratory-ml/kevin/venv/lib/python3.10/site-packages/ray/tune/trainable/trainable.py", line 331, in train
    raise skipped from exception_cause(skipped)
  File "/zfs/projects/darc/wolee_edehaan_suzienoh-exploratory-ml/kevin/venv/lib/python3.10/site-packages/ray/air/_internal/util.py", line 98, in run
    self._ret = self._target(*self._args, **self._kwargs)
  File "/zfs/projects/darc/wolee_edehaan_suzienoh-exploratory-ml/kevin/venv/lib/python3.10/site-packages/ray/tune/trainable/function_trainable.py", line 45, in <lambda>
    training_func=lambda: self._trainable_func(self.config),
  File "/zfs/projects/darc/wolee_edehaan_suzienoh-exploratory-ml/kevin/venv/lib/python3.10/site-packages/ray/tune/trainable/function_trainable.py", line 248, in _trainable_func
    output = fn()
  File "/zfs/projects/darc/wolee_edehaan_suzienoh-exploratory-ml/kevin/venv/lib/python3.10/site-packages/ray/tune/trainable/util.py", line 130, in inner
    return trainable(config, **fn_kwargs)
  File "/tmp/ray/session_2024-07-02_22-54-41_444445_3481399/runtime_resources/working_dir_files/_ray_pkg_355028f0108691b8/model_data_nn.py", line 159, in train_fnn
    loss_function = nn.MSE
AttributeError: module 'torch.nn' has no attribute 'MSE'
2024-07-02 22:54:59,734	ERROR tune_controller.py:1331 -- Trial task failed for trial train_fnn_13ce7_00003
Traceback (most recent call last):
  File "/zfs/projects/darc/wolee_edehaan_suzienoh-exploratory-ml/kevin/venv/lib/python3.10/site-packages/ray/air/execution/_internal/event_manager.py", line 110, in resolve_future
    result = ray.get(future)
  File "/zfs/projects/darc/wolee_edehaan_suzienoh-exploratory-ml/kevin/venv/lib/python3.10/site-packages/ray/_private/auto_init_hook.py", line 21, in auto_init_wrapper
    return fn(*args, **kwargs)
  File "/zfs/projects/darc/wolee_edehaan_suzienoh-exploratory-ml/kevin/venv/lib/python3.10/site-packages/ray/_private/client_mode_hook.py", line 103, in wrapper
    return func(*args, **kwargs)
  File "/zfs/projects/darc/wolee_edehaan_suzienoh-exploratory-ml/kevin/venv/lib/python3.10/site-packages/ray/_private/worker.py", line 2613, in get
    values, debugger_breakpoint = worker.get_objects(object_refs, timeout=timeout)
  File "/zfs/projects/darc/wolee_edehaan_suzienoh-exploratory-ml/kevin/venv/lib/python3.10/site-packages/ray/_private/worker.py", line 861, in get_objects
    raise value.as_instanceof_cause()
ray.exceptions.RayTaskError(AttributeError): [36mray::ImplicitFunc.train()[39m (pid=3489877, ip=10.112.2.40, actor_id=f1e73f77ed5e73a0d25d6d6201000000, repr=train_fnn)
  File "/zfs/projects/darc/wolee_edehaan_suzienoh-exploratory-ml/kevin/venv/lib/python3.10/site-packages/ray/tune/trainable/trainable.py", line 331, in train
    raise skipped from exception_cause(skipped)
  File "/zfs/projects/darc/wolee_edehaan_suzienoh-exploratory-ml/kevin/venv/lib/python3.10/site-packages/ray/air/_internal/util.py", line 98, in run
    self._ret = self._target(*self._args, **self._kwargs)
  File "/zfs/projects/darc/wolee_edehaan_suzienoh-exploratory-ml/kevin/venv/lib/python3.10/site-packages/ray/tune/trainable/function_trainable.py", line 45, in <lambda>
    training_func=lambda: self._trainable_func(self.config),
  File "/zfs/projects/darc/wolee_edehaan_suzienoh-exploratory-ml/kevin/venv/lib/python3.10/site-packages/ray/tune/trainable/function_trainable.py", line 248, in _trainable_func
    output = fn()
  File "/zfs/projects/darc/wolee_edehaan_suzienoh-exploratory-ml/kevin/venv/lib/python3.10/site-packages/ray/tune/trainable/util.py", line 130, in inner
    return trainable(config, **fn_kwargs)
  File "/tmp/ray/session_2024-07-02_22-54-41_444445_3481399/runtime_resources/working_dir_files/_ray_pkg_355028f0108691b8/model_data_nn.py", line 159, in train_fnn
    loss_function = nn.MSE
AttributeError: module 'torch.nn' has no attribute 'MSE'
2024-07-02 22:55:05,915	ERROR tune_controller.py:1331 -- Trial task failed for trial train_fnn_13ce7_00005
Traceback (most recent call last):
  File "/zfs/projects/darc/wolee_edehaan_suzienoh-exploratory-ml/kevin/venv/lib/python3.10/site-packages/ray/air/execution/_internal/event_manager.py", line 110, in resolve_future
    result = ray.get(future)
  File "/zfs/projects/darc/wolee_edehaan_suzienoh-exploratory-ml/kevin/venv/lib/python3.10/site-packages/ray/_private/auto_init_hook.py", line 21, in auto_init_wrapper
    return fn(*args, **kwargs)
  File "/zfs/projects/darc/wolee_edehaan_suzienoh-exploratory-ml/kevin/venv/lib/python3.10/site-packages/ray/_private/client_mode_hook.py", line 103, in wrapper
    return func(*args, **kwargs)
  File "/zfs/projects/darc/wolee_edehaan_suzienoh-exploratory-ml/kevin/venv/lib/python3.10/site-packages/ray/_private/worker.py", line 2613, in get
    values, debugger_breakpoint = worker.get_objects(object_refs, timeout=timeout)
  File "/zfs/projects/darc/wolee_edehaan_suzienoh-exploratory-ml/kevin/venv/lib/python3.10/site-packages/ray/_private/worker.py", line 861, in get_objects
    raise value.as_instanceof_cause()
ray.exceptions.RayTaskError(AttributeError): [36mray::ImplicitFunc.train()[39m (pid=3490041, ip=10.112.2.40, actor_id=18e959027df6c6dae968b28a01000000, repr=train_fnn)
  File "/zfs/projects/darc/wolee_edehaan_suzienoh-exploratory-ml/kevin/venv/lib/python3.10/site-packages/ray/tune/trainable/trainable.py", line 331, in train
    raise skipped from exception_cause(skipped)
  File "/zfs/projects/darc/wolee_edehaan_suzienoh-exploratory-ml/kevin/venv/lib/python3.10/site-packages/ray/air/_internal/util.py", line 98, in run
    self._ret = self._target(*self._args, **self._kwargs)
  File "/zfs/projects/darc/wolee_edehaan_suzienoh-exploratory-ml/kevin/venv/lib/python3.10/site-packages/ray/tune/trainable/function_trainable.py", line 45, in <lambda>
    training_func=lambda: self._trainable_func(self.config),
  File "/zfs/projects/darc/wolee_edehaan_suzienoh-exploratory-ml/kevin/venv/lib/python3.10/site-packages/ray/tune/trainable/function_trainable.py", line 248, in _trainable_func
    output = fn()
  File "/zfs/projects/darc/wolee_edehaan_suzienoh-exploratory-ml/kevin/venv/lib/python3.10/site-packages/ray/tune/trainable/util.py", line 130, in inner
    return trainable(config, **fn_kwargs)
  File "/tmp/ray/session_2024-07-02_22-54-41_444445_3481399/runtime_resources/working_dir_files/_ray_pkg_355028f0108691b8/model_data_nn.py", line 159, in train_fnn
    loss_function = nn.MSE
AttributeError: module 'torch.nn' has no attribute 'MSE'
2024-07-02 22:55:05,925	ERROR tune_controller.py:1331 -- Trial task failed for trial train_fnn_13ce7_00004
Traceback (most recent call last):
  File "/zfs/projects/darc/wolee_edehaan_suzienoh-exploratory-ml/kevin/venv/lib/python3.10/site-packages/ray/air/execution/_internal/event_manager.py", line 110, in resolve_future
    result = ray.get(future)
  File "/zfs/projects/darc/wolee_edehaan_suzienoh-exploratory-ml/kevin/venv/lib/python3.10/site-packages/ray/_private/auto_init_hook.py", line 21, in auto_init_wrapper
    return fn(*args, **kwargs)
  File "/zfs/projects/darc/wolee_edehaan_suzienoh-exploratory-ml/kevin/venv/lib/python3.10/site-packages/ray/_private/client_mode_hook.py", line 103, in wrapper
    return func(*args, **kwargs)
  File "/zfs/projects/darc/wolee_edehaan_suzienoh-exploratory-ml/kevin/venv/lib/python3.10/site-packages/ray/_private/worker.py", line 2613, in get
    values, debugger_breakpoint = worker.get_objects(object_refs, timeout=timeout)
  File "/zfs/projects/darc/wolee_edehaan_suzienoh-exploratory-ml/kevin/venv/lib/python3.10/site-packages/ray/_private/worker.py", line 861, in get_objects
    raise value.as_instanceof_cause()
ray.exceptions.RayTaskError(AttributeError): [36mray::ImplicitFunc.train()[39m (pid=3490040, ip=10.112.2.40, actor_id=262561994931d051154a221101000000, repr=train_fnn)
  File "/zfs/projects/darc/wolee_edehaan_suzienoh-exploratory-ml/kevin/venv/lib/python3.10/site-packages/ray/tune/trainable/trainable.py", line 331, in train
    raise skipped from exception_cause(skipped)
  File "/zfs/projects/darc/wolee_edehaan_suzienoh-exploratory-ml/kevin/venv/lib/python3.10/site-packages/ray/air/_internal/util.py", line 98, in run
    self._ret = self._target(*self._args, **self._kwargs)
  File "/zfs/projects/darc/wolee_edehaan_suzienoh-exploratory-ml/kevin/venv/lib/python3.10/site-packages/ray/tune/trainable/function_trainable.py", line 45, in <lambda>
    training_func=lambda: self._trainable_func(self.config),
  File "/zfs/projects/darc/wolee_edehaan_suzienoh-exploratory-ml/kevin/venv/lib/python3.10/site-packages/ray/tune/trainable/function_trainable.py", line 248, in _trainable_func
    output = fn()
  File "/zfs/projects/darc/wolee_edehaan_suzienoh-exploratory-ml/kevin/venv/lib/python3.10/site-packages/ray/tune/trainable/util.py", line 130, in inner
    return trainable(config, **fn_kwargs)
  File "/tmp/ray/session_2024-07-02_22-54-41_444445_3481399/runtime_resources/working_dir_files/_ray_pkg_355028f0108691b8/model_data_nn.py", line 159, in train_fnn
    loss_function = nn.MSE
AttributeError: module 'torch.nn' has no attribute 'MSE'
2024-07-02 22:55:12,421	ERROR tune_controller.py:1331 -- Trial task failed for trial train_fnn_13ce7_00006
Traceback (most recent call last):
  File "/zfs/projects/darc/wolee_edehaan_suzienoh-exploratory-ml/kevin/venv/lib/python3.10/site-packages/ray/air/execution/_internal/event_manager.py", line 110, in resolve_future
    result = ray.get(future)
  File "/zfs/projects/darc/wolee_edehaan_suzienoh-exploratory-ml/kevin/venv/lib/python3.10/site-packages/ray/_private/auto_init_hook.py", line 21, in auto_init_wrapper
    return fn(*args, **kwargs)
  File "/zfs/projects/darc/wolee_edehaan_suzienoh-exploratory-ml/kevin/venv/lib/python3.10/site-packages/ray/_private/client_mode_hook.py", line 103, in wrapper
    return func(*args, **kwargs)
  File "/zfs/projects/darc/wolee_edehaan_suzienoh-exploratory-ml/kevin/venv/lib/python3.10/site-packages/ray/_private/worker.py", line 2613, in get
    values, debugger_breakpoint = worker.get_objects(object_refs, timeout=timeout)
  File "/zfs/projects/darc/wolee_edehaan_suzienoh-exploratory-ml/kevin/venv/lib/python3.10/site-packages/ray/_private/worker.py", line 861, in get_objects
    raise value.as_instanceof_cause()
ray.exceptions.RayTaskError(AttributeError): [36mray::ImplicitFunc.train()[39m (pid=3496474, ip=10.112.2.40, actor_id=7191aec00751b701ad57e63801000000, repr=train_fnn)
  File "/zfs/projects/darc/wolee_edehaan_suzienoh-exploratory-ml/kevin/venv/lib/python3.10/site-packages/ray/tune/trainable/trainable.py", line 331, in train
    raise skipped from exception_cause(skipped)
  File "/zfs/projects/darc/wolee_edehaan_suzienoh-exploratory-ml/kevin/venv/lib/python3.10/site-packages/ray/air/_internal/util.py", line 98, in run
    self._ret = self._target(*self._args, **self._kwargs)
  File "/zfs/projects/darc/wolee_edehaan_suzienoh-exploratory-ml/kevin/venv/lib/python3.10/site-packages/ray/tune/trainable/function_trainable.py", line 45, in <lambda>
    training_func=lambda: self._trainable_func(self.config),
  File "/zfs/projects/darc/wolee_edehaan_suzienoh-exploratory-ml/kevin/venv/lib/python3.10/site-packages/ray/tune/trainable/function_trainable.py", line 248, in _trainable_func
    output = fn()
  File "/zfs/projects/darc/wolee_edehaan_suzienoh-exploratory-ml/kevin/venv/lib/python3.10/site-packages/ray/tune/trainable/util.py", line 130, in inner
    return trainable(config, **fn_kwargs)
  File "/tmp/ray/session_2024-07-02_22-54-41_444445_3481399/runtime_resources/working_dir_files/_ray_pkg_355028f0108691b8/model_data_nn.py", line 159, in train_fnn
    loss_function = nn.MSE
AttributeError: module 'torch.nn' has no attribute 'MSE'
2024-07-02 22:55:12,552	ERROR tune_controller.py:1331 -- Trial task failed for trial train_fnn_13ce7_00007
Traceback (most recent call last):
  File "/zfs/projects/darc/wolee_edehaan_suzienoh-exploratory-ml/kevin/venv/lib/python3.10/site-packages/ray/air/execution/_internal/event_manager.py", line 110, in resolve_future
    result = ray.get(future)
  File "/zfs/projects/darc/wolee_edehaan_suzienoh-exploratory-ml/kevin/venv/lib/python3.10/site-packages/ray/_private/auto_init_hook.py", line 21, in auto_init_wrapper
    return fn(*args, **kwargs)
  File "/zfs/projects/darc/wolee_edehaan_suzienoh-exploratory-ml/kevin/venv/lib/python3.10/site-packages/ray/_private/client_mode_hook.py", line 103, in wrapper
    return func(*args, **kwargs)
  File "/zfs/projects/darc/wolee_edehaan_suzienoh-exploratory-ml/kevin/venv/lib/python3.10/site-packages/ray/_private/worker.py", line 2613, in get
    values, debugger_breakpoint = worker.get_objects(object_refs, timeout=timeout)
  File "/zfs/projects/darc/wolee_edehaan_suzienoh-exploratory-ml/kevin/venv/lib/python3.10/site-packages/ray/_private/worker.py", line 861, in get_objects
    raise value.as_instanceof_cause()
ray.exceptions.RayTaskError(AttributeError): [36mray::ImplicitFunc.train()[39m (pid=3496485, ip=10.112.2.40, actor_id=6f716b70060cb5c8b7b6638201000000, repr=train_fnn)
  File "/zfs/projects/darc/wolee_edehaan_suzienoh-exploratory-ml/kevin/venv/lib/python3.10/site-packages/ray/tune/trainable/trainable.py", line 331, in train
    raise skipped from exception_cause(skipped)
  File "/zfs/projects/darc/wolee_edehaan_suzienoh-exploratory-ml/kevin/venv/lib/python3.10/site-packages/ray/air/_internal/util.py", line 98, in run
    self._ret = self._target(*self._args, **self._kwargs)
  File "/zfs/projects/darc/wolee_edehaan_suzienoh-exploratory-ml/kevin/venv/lib/python3.10/site-packages/ray/tune/trainable/function_trainable.py", line 45, in <lambda>
    training_func=lambda: self._trainable_func(self.config),
  File "/zfs/projects/darc/wolee_edehaan_suzienoh-exploratory-ml/kevin/venv/lib/python3.10/site-packages/ray/tune/trainable/function_trainable.py", line 248, in _trainable_func
    output = fn()
  File "/zfs/projects/darc/wolee_edehaan_suzienoh-exploratory-ml/kevin/venv/lib/python3.10/site-packages/ray/tune/trainable/util.py", line 130, in inner
    return trainable(config, **fn_kwargs)
  File "/tmp/ray/session_2024-07-02_22-54-41_444445_3481399/runtime_resources/working_dir_files/_ray_pkg_355028f0108691b8/model_data_nn.py", line 159, in train_fnn
    loss_function = nn.MSE
AttributeError: module 'torch.nn' has no attribute 'MSE'
2024-07-02 22:55:17,745	ERROR tune_controller.py:1331 -- Trial task failed for trial train_fnn_13ce7_00009
Traceback (most recent call last):
  File "/zfs/projects/darc/wolee_edehaan_suzienoh-exploratory-ml/kevin/venv/lib/python3.10/site-packages/ray/air/execution/_internal/event_manager.py", line 110, in resolve_future
    result = ray.get(future)
  File "/zfs/projects/darc/wolee_edehaan_suzienoh-exploratory-ml/kevin/venv/lib/python3.10/site-packages/ray/_private/auto_init_hook.py", line 21, in auto_init_wrapper
    return fn(*args, **kwargs)
  File "/zfs/projects/darc/wolee_edehaan_suzienoh-exploratory-ml/kevin/venv/lib/python3.10/site-packages/ray/_private/client_mode_hook.py", line 103, in wrapper
    return func(*args, **kwargs)
  File "/zfs/projects/darc/wolee_edehaan_suzienoh-exploratory-ml/kevin/venv/lib/python3.10/site-packages/ray/_private/worker.py", line 2613, in get
    values, debugger_breakpoint = worker.get_objects(object_refs, timeout=timeout)
  File "/zfs/projects/darc/wolee_edehaan_suzienoh-exploratory-ml/kevin/venv/lib/python3.10/site-packages/ray/_private/worker.py", line 861, in get_objects
    raise value.as_instanceof_cause()
ray.exceptions.RayTaskError(AttributeError): [36mray::ImplicitFunc.train()[39m (pid=3498407, ip=10.112.2.40, actor_id=8beef59374c6e1b104e8bc3b01000000, repr=train_fnn)
  File "/zfs/projects/darc/wolee_edehaan_suzienoh-exploratory-ml/kevin/venv/lib/python3.10/site-packages/ray/tune/trainable/trainable.py", line 331, in train
    raise skipped from exception_cause(skipped)
  File "/zfs/projects/darc/wolee_edehaan_suzienoh-exploratory-ml/kevin/venv/lib/python3.10/site-packages/ray/air/_internal/util.py", line 98, in run
    self._ret = self._target(*self._args, **self._kwargs)
  File "/zfs/projects/darc/wolee_edehaan_suzienoh-exploratory-ml/kevin/venv/lib/python3.10/site-packages/ray/tune/trainable/function_trainable.py", line 45, in <lambda>
    training_func=lambda: self._trainable_func(self.config),
  File "/zfs/projects/darc/wolee_edehaan_suzienoh-exploratory-ml/kevin/venv/lib/python3.10/site-packages/ray/tune/trainable/function_trainable.py", line 248, in _trainable_func
    output = fn()
  File "/zfs/projects/darc/wolee_edehaan_suzienoh-exploratory-ml/kevin/venv/lib/python3.10/site-packages/ray/tune/trainable/util.py", line 130, in inner
    return trainable(config, **fn_kwargs)
  File "/tmp/ray/session_2024-07-02_22-54-41_444445_3481399/runtime_resources/working_dir_files/_ray_pkg_355028f0108691b8/model_data_nn.py", line 159, in train_fnn
    loss_function = nn.MSE
AttributeError: module 'torch.nn' has no attribute 'MSE'
2024-07-02 22:55:17,754	ERROR tune_controller.py:1331 -- Trial task failed for trial train_fnn_13ce7_00008
Traceback (most recent call last):
  File "/zfs/projects/darc/wolee_edehaan_suzienoh-exploratory-ml/kevin/venv/lib/python3.10/site-packages/ray/air/execution/_internal/event_manager.py", line 110, in resolve_future
    result = ray.get(future)
  File "/zfs/projects/darc/wolee_edehaan_suzienoh-exploratory-ml/kevin/venv/lib/python3.10/site-packages/ray/_private/auto_init_hook.py", line 21, in auto_init_wrapper
    return fn(*args, **kwargs)
  File "/zfs/projects/darc/wolee_edehaan_suzienoh-exploratory-ml/kevin/venv/lib/python3.10/site-packages/ray/_private/client_mode_hook.py", line 103, in wrapper
    return func(*args, **kwargs)
  File "/zfs/projects/darc/wolee_edehaan_suzienoh-exploratory-ml/kevin/venv/lib/python3.10/site-packages/ray/_private/worker.py", line 2613, in get
    values, debugger_breakpoint = worker.get_objects(object_refs, timeout=timeout)
  File "/zfs/projects/darc/wolee_edehaan_suzienoh-exploratory-ml/kevin/venv/lib/python3.10/site-packages/ray/_private/worker.py", line 861, in get_objects
    raise value.as_instanceof_cause()
ray.exceptions.RayTaskError(AttributeError): [36mray::ImplicitFunc.train()[39m (pid=3498406, ip=10.112.2.40, actor_id=dc83b1fff1084799e945347601000000, repr=train_fnn)
  File "/zfs/projects/darc/wolee_edehaan_suzienoh-exploratory-ml/kevin/venv/lib/python3.10/site-packages/ray/tune/trainable/trainable.py", line 331, in train
    raise skipped from exception_cause(skipped)
  File "/zfs/projects/darc/wolee_edehaan_suzienoh-exploratory-ml/kevin/venv/lib/python3.10/site-packages/ray/air/_internal/util.py", line 98, in run
    self._ret = self._target(*self._args, **self._kwargs)
  File "/zfs/projects/darc/wolee_edehaan_suzienoh-exploratory-ml/kevin/venv/lib/python3.10/site-packages/ray/tune/trainable/function_trainable.py", line 45, in <lambda>
    training_func=lambda: self._trainable_func(self.config),
  File "/zfs/projects/darc/wolee_edehaan_suzienoh-exploratory-ml/kevin/venv/lib/python3.10/site-packages/ray/tune/trainable/function_trainable.py", line 248, in _trainable_func
    output = fn()
  File "/zfs/projects/darc/wolee_edehaan_suzienoh-exploratory-ml/kevin/venv/lib/python3.10/site-packages/ray/tune/trainable/util.py", line 130, in inner
    return trainable(config, **fn_kwargs)
  File "/tmp/ray/session_2024-07-02_22-54-41_444445_3481399/runtime_resources/working_dir_files/_ray_pkg_355028f0108691b8/model_data_nn.py", line 159, in train_fnn
    loss_function = nn.MSE
AttributeError: module 'torch.nn' has no attribute 'MSE'
2024-07-02 22:55:24,501	ERROR tune_controller.py:1331 -- Trial task failed for trial train_fnn_13ce7_00010
Traceback (most recent call last):
  File "/zfs/projects/darc/wolee_edehaan_suzienoh-exploratory-ml/kevin/venv/lib/python3.10/site-packages/ray/air/execution/_internal/event_manager.py", line 110, in resolve_future
    result = ray.get(future)
  File "/zfs/projects/darc/wolee_edehaan_suzienoh-exploratory-ml/kevin/venv/lib/python3.10/site-packages/ray/_private/auto_init_hook.py", line 21, in auto_init_wrapper
    return fn(*args, **kwargs)
  File "/zfs/projects/darc/wolee_edehaan_suzienoh-exploratory-ml/kevin/venv/lib/python3.10/site-packages/ray/_private/client_mode_hook.py", line 103, in wrapper
    return func(*args, **kwargs)
  File "/zfs/projects/darc/wolee_edehaan_suzienoh-exploratory-ml/kevin/venv/lib/python3.10/site-packages/ray/_private/worker.py", line 2613, in get
    values, debugger_breakpoint = worker.get_objects(object_refs, timeout=timeout)
  File "/zfs/projects/darc/wolee_edehaan_suzienoh-exploratory-ml/kevin/venv/lib/python3.10/site-packages/ray/_private/worker.py", line 861, in get_objects
    raise value.as_instanceof_cause()
ray.exceptions.RayTaskError(AttributeError): [36mray::ImplicitFunc.train()[39m (pid=3498567, ip=10.112.2.40, actor_id=e0a1816933647dbd465d35eb01000000, repr=train_fnn)
  File "/zfs/projects/darc/wolee_edehaan_suzienoh-exploratory-ml/kevin/venv/lib/python3.10/site-packages/ray/tune/trainable/trainable.py", line 331, in train
    raise skipped from exception_cause(skipped)
  File "/zfs/projects/darc/wolee_edehaan_suzienoh-exploratory-ml/kevin/venv/lib/python3.10/site-packages/ray/air/_internal/util.py", line 98, in run
    self._ret = self._target(*self._args, **self._kwargs)
  File "/zfs/projects/darc/wolee_edehaan_suzienoh-exploratory-ml/kevin/venv/lib/python3.10/site-packages/ray/tune/trainable/function_trainable.py", line 45, in <lambda>
    training_func=lambda: self._trainable_func(self.config),
  File "/zfs/projects/darc/wolee_edehaan_suzienoh-exploratory-ml/kevin/venv/lib/python3.10/site-packages/ray/tune/trainable/function_trainable.py", line 248, in _trainable_func
    output = fn()
  File "/zfs/projects/darc/wolee_edehaan_suzienoh-exploratory-ml/kevin/venv/lib/python3.10/site-packages/ray/tune/trainable/util.py", line 130, in inner
    return trainable(config, **fn_kwargs)
  File "/tmp/ray/session_2024-07-02_22-54-41_444445_3481399/runtime_resources/working_dir_files/_ray_pkg_355028f0108691b8/model_data_nn.py", line 159, in train_fnn
    loss_function = nn.MSE
AttributeError: module 'torch.nn' has no attribute 'MSE'
2024-07-02 22:55:24,509	ERROR tune_controller.py:1331 -- Trial task failed for trial train_fnn_13ce7_00011
Traceback (most recent call last):
  File "/zfs/projects/darc/wolee_edehaan_suzienoh-exploratory-ml/kevin/venv/lib/python3.10/site-packages/ray/air/execution/_internal/event_manager.py", line 110, in resolve_future
    result = ray.get(future)
  File "/zfs/projects/darc/wolee_edehaan_suzienoh-exploratory-ml/kevin/venv/lib/python3.10/site-packages/ray/_private/auto_init_hook.py", line 21, in auto_init_wrapper
    return fn(*args, **kwargs)
  File "/zfs/projects/darc/wolee_edehaan_suzienoh-exploratory-ml/kevin/venv/lib/python3.10/site-packages/ray/_private/client_mode_hook.py", line 103, in wrapper
    return func(*args, **kwargs)
  File "/zfs/projects/darc/wolee_edehaan_suzienoh-exploratory-ml/kevin/venv/lib/python3.10/site-packages/ray/_private/worker.py", line 2613, in get
    values, debugger_breakpoint = worker.get_objects(object_refs, timeout=timeout)
  File "/zfs/projects/darc/wolee_edehaan_suzienoh-exploratory-ml/kevin/venv/lib/python3.10/site-packages/ray/_private/worker.py", line 861, in get_objects
    raise value.as_instanceof_cause()
ray.exceptions.RayTaskError(AttributeError): [36mray::ImplicitFunc.train()[39m (pid=3498568, ip=10.112.2.40, actor_id=190e0ded6ef7c94e0da4314c01000000, repr=train_fnn)
  File "/zfs/projects/darc/wolee_edehaan_suzienoh-exploratory-ml/kevin/venv/lib/python3.10/site-packages/ray/tune/trainable/trainable.py", line 331, in train
    raise skipped from exception_cause(skipped)
  File "/zfs/projects/darc/wolee_edehaan_suzienoh-exploratory-ml/kevin/venv/lib/python3.10/site-packages/ray/air/_internal/util.py", line 98, in run
    self._ret = self._target(*self._args, **self._kwargs)
  File "/zfs/projects/darc/wolee_edehaan_suzienoh-exploratory-ml/kevin/venv/lib/python3.10/site-packages/ray/tune/trainable/function_trainable.py", line 45, in <lambda>
    training_func=lambda: self._trainable_func(self.config),
  File "/zfs/projects/darc/wolee_edehaan_suzienoh-exploratory-ml/kevin/venv/lib/python3.10/site-packages/ray/tune/trainable/function_trainable.py", line 248, in _trainable_func
    output = fn()
  File "/zfs/projects/darc/wolee_edehaan_suzienoh-exploratory-ml/kevin/venv/lib/python3.10/site-packages/ray/tune/trainable/util.py", line 130, in inner
    return trainable(config, **fn_kwargs)
  File "/tmp/ray/session_2024-07-02_22-54-41_444445_3481399/runtime_resources/working_dir_files/_ray_pkg_355028f0108691b8/model_data_nn.py", line 159, in train_fnn
    loss_function = nn.MSE
AttributeError: module 'torch.nn' has no attribute 'MSE'
2024-07-02 22:55:30,799	ERROR tune_controller.py:1331 -- Trial task failed for trial train_fnn_13ce7_00012
Traceback (most recent call last):
  File "/zfs/projects/darc/wolee_edehaan_suzienoh-exploratory-ml/kevin/venv/lib/python3.10/site-packages/ray/air/execution/_internal/event_manager.py", line 110, in resolve_future
    result = ray.get(future)
  File "/zfs/projects/darc/wolee_edehaan_suzienoh-exploratory-ml/kevin/venv/lib/python3.10/site-packages/ray/_private/auto_init_hook.py", line 21, in auto_init_wrapper
    return fn(*args, **kwargs)
  File "/zfs/projects/darc/wolee_edehaan_suzienoh-exploratory-ml/kevin/venv/lib/python3.10/site-packages/ray/_private/client_mode_hook.py", line 103, in wrapper
    return func(*args, **kwargs)
  File "/zfs/projects/darc/wolee_edehaan_suzienoh-exploratory-ml/kevin/venv/lib/python3.10/site-packages/ray/_private/worker.py", line 2613, in get
    values, debugger_breakpoint = worker.get_objects(object_refs, timeout=timeout)
  File "/zfs/projects/darc/wolee_edehaan_suzienoh-exploratory-ml/kevin/venv/lib/python3.10/site-packages/ray/_private/worker.py", line 861, in get_objects
    raise value.as_instanceof_cause()
ray.exceptions.RayTaskError(AttributeError): [36mray::ImplicitFunc.train()[39m (pid=3498728, ip=10.112.2.40, actor_id=ba93148fdbe8814d70d9114801000000, repr=train_fnn)
  File "/zfs/projects/darc/wolee_edehaan_suzienoh-exploratory-ml/kevin/venv/lib/python3.10/site-packages/ray/tune/trainable/trainable.py", line 331, in train
    raise skipped from exception_cause(skipped)
  File "/zfs/projects/darc/wolee_edehaan_suzienoh-exploratory-ml/kevin/venv/lib/python3.10/site-packages/ray/air/_internal/util.py", line 98, in run
    self._ret = self._target(*self._args, **self._kwargs)
  File "/zfs/projects/darc/wolee_edehaan_suzienoh-exploratory-ml/kevin/venv/lib/python3.10/site-packages/ray/tune/trainable/function_trainable.py", line 45, in <lambda>
    training_func=lambda: self._trainable_func(self.config),
  File "/zfs/projects/darc/wolee_edehaan_suzienoh-exploratory-ml/kevin/venv/lib/python3.10/site-packages/ray/tune/trainable/function_trainable.py", line 248, in _trainable_func
    output = fn()
  File "/zfs/projects/darc/wolee_edehaan_suzienoh-exploratory-ml/kevin/venv/lib/python3.10/site-packages/ray/tune/trainable/util.py", line 130, in inner
    return trainable(config, **fn_kwargs)
  File "/tmp/ray/session_2024-07-02_22-54-41_444445_3481399/runtime_resources/working_dir_files/_ray_pkg_355028f0108691b8/model_data_nn.py", line 159, in train_fnn
    loss_function = nn.MSE
AttributeError: module 'torch.nn' has no attribute 'MSE'
2024-07-02 22:55:30,808	ERROR tune_controller.py:1331 -- Trial task failed for trial train_fnn_13ce7_00013
Traceback (most recent call last):
  File "/zfs/projects/darc/wolee_edehaan_suzienoh-exploratory-ml/kevin/venv/lib/python3.10/site-packages/ray/air/execution/_internal/event_manager.py", line 110, in resolve_future
    result = ray.get(future)
  File "/zfs/projects/darc/wolee_edehaan_suzienoh-exploratory-ml/kevin/venv/lib/python3.10/site-packages/ray/_private/auto_init_hook.py", line 21, in auto_init_wrapper
    return fn(*args, **kwargs)
  File "/zfs/projects/darc/wolee_edehaan_suzienoh-exploratory-ml/kevin/venv/lib/python3.10/site-packages/ray/_private/client_mode_hook.py", line 103, in wrapper
    return func(*args, **kwargs)
  File "/zfs/projects/darc/wolee_edehaan_suzienoh-exploratory-ml/kevin/venv/lib/python3.10/site-packages/ray/_private/worker.py", line 2613, in get
    values, debugger_breakpoint = worker.get_objects(object_refs, timeout=timeout)
  File "/zfs/projects/darc/wolee_edehaan_suzienoh-exploratory-ml/kevin/venv/lib/python3.10/site-packages/ray/_private/worker.py", line 861, in get_objects
    raise value.as_instanceof_cause()
ray.exceptions.RayTaskError(AttributeError): [36mray::ImplicitFunc.train()[39m (pid=3498729, ip=10.112.2.40, actor_id=41ce29b23722cc9f0138161601000000, repr=train_fnn)
  File "/zfs/projects/darc/wolee_edehaan_suzienoh-exploratory-ml/kevin/venv/lib/python3.10/site-packages/ray/tune/trainable/trainable.py", line 331, in train
    raise skipped from exception_cause(skipped)
  File "/zfs/projects/darc/wolee_edehaan_suzienoh-exploratory-ml/kevin/venv/lib/python3.10/site-packages/ray/air/_internal/util.py", line 98, in run
    self._ret = self._target(*self._args, **self._kwargs)
  File "/zfs/projects/darc/wolee_edehaan_suzienoh-exploratory-ml/kevin/venv/lib/python3.10/site-packages/ray/tune/trainable/function_trainable.py", line 45, in <lambda>
    training_func=lambda: self._trainable_func(self.config),
  File "/zfs/projects/darc/wolee_edehaan_suzienoh-exploratory-ml/kevin/venv/lib/python3.10/site-packages/ray/tune/trainable/function_trainable.py", line 248, in _trainable_func
    output = fn()
  File "/zfs/projects/darc/wolee_edehaan_suzienoh-exploratory-ml/kevin/venv/lib/python3.10/site-packages/ray/tune/trainable/util.py", line 130, in inner
    return trainable(config, **fn_kwargs)
  File "/tmp/ray/session_2024-07-02_22-54-41_444445_3481399/runtime_resources/working_dir_files/_ray_pkg_355028f0108691b8/model_data_nn.py", line 159, in train_fnn
    loss_function = nn.MSE
AttributeError: module 'torch.nn' has no attribute 'MSE'
2024-07-02 22:55:37,155	ERROR tune_controller.py:1331 -- Trial task failed for trial train_fnn_13ce7_00015
Traceback (most recent call last):
  File "/zfs/projects/darc/wolee_edehaan_suzienoh-exploratory-ml/kevin/venv/lib/python3.10/site-packages/ray/air/execution/_internal/event_manager.py", line 110, in resolve_future
    result = ray.get(future)
  File "/zfs/projects/darc/wolee_edehaan_suzienoh-exploratory-ml/kevin/venv/lib/python3.10/site-packages/ray/_private/auto_init_hook.py", line 21, in auto_init_wrapper
    return fn(*args, **kwargs)
  File "/zfs/projects/darc/wolee_edehaan_suzienoh-exploratory-ml/kevin/venv/lib/python3.10/site-packages/ray/_private/client_mode_hook.py", line 103, in wrapper
    return func(*args, **kwargs)
  File "/zfs/projects/darc/wolee_edehaan_suzienoh-exploratory-ml/kevin/venv/lib/python3.10/site-packages/ray/_private/worker.py", line 2613, in get
    values, debugger_breakpoint = worker.get_objects(object_refs, timeout=timeout)
  File "/zfs/projects/darc/wolee_edehaan_suzienoh-exploratory-ml/kevin/venv/lib/python3.10/site-packages/ray/_private/worker.py", line 861, in get_objects
    raise value.as_instanceof_cause()
ray.exceptions.RayTaskError(AttributeError): [36mray::ImplicitFunc.train()[39m (pid=3498893, ip=10.112.2.40, actor_id=4546acd9a010a3be68fc4dad01000000, repr=train_fnn)
  File "/zfs/projects/darc/wolee_edehaan_suzienoh-exploratory-ml/kevin/venv/lib/python3.10/site-packages/ray/tune/trainable/trainable.py", line 331, in train
    raise skipped from exception_cause(skipped)
  File "/zfs/projects/darc/wolee_edehaan_suzienoh-exploratory-ml/kevin/venv/lib/python3.10/site-packages/ray/air/_internal/util.py", line 98, in run
    self._ret = self._target(*self._args, **self._kwargs)
  File "/zfs/projects/darc/wolee_edehaan_suzienoh-exploratory-ml/kevin/venv/lib/python3.10/site-packages/ray/tune/trainable/function_trainable.py", line 45, in <lambda>
    training_func=lambda: self._trainable_func(self.config),
  File "/zfs/projects/darc/wolee_edehaan_suzienoh-exploratory-ml/kevin/venv/lib/python3.10/site-packages/ray/tune/trainable/function_trainable.py", line 248, in _trainable_func
    output = fn()
  File "/zfs/projects/darc/wolee_edehaan_suzienoh-exploratory-ml/kevin/venv/lib/python3.10/site-packages/ray/tune/trainable/util.py", line 130, in inner
    return trainable(config, **fn_kwargs)
  File "/tmp/ray/session_2024-07-02_22-54-41_444445_3481399/runtime_resources/working_dir_files/_ray_pkg_355028f0108691b8/model_data_nn.py", line 159, in train_fnn
    loss_function = nn.MSE
AttributeError: module 'torch.nn' has no attribute 'MSE'
2024-07-02 22:55:37,266	ERROR tune_controller.py:1331 -- Trial task failed for trial train_fnn_13ce7_00014
Traceback (most recent call last):
  File "/zfs/projects/darc/wolee_edehaan_suzienoh-exploratory-ml/kevin/venv/lib/python3.10/site-packages/ray/air/execution/_internal/event_manager.py", line 110, in resolve_future
    result = ray.get(future)
  File "/zfs/projects/darc/wolee_edehaan_suzienoh-exploratory-ml/kevin/venv/lib/python3.10/site-packages/ray/_private/auto_init_hook.py", line 21, in auto_init_wrapper
    return fn(*args, **kwargs)
  File "/zfs/projects/darc/wolee_edehaan_suzienoh-exploratory-ml/kevin/venv/lib/python3.10/site-packages/ray/_private/client_mode_hook.py", line 103, in wrapper
    return func(*args, **kwargs)
  File "/zfs/projects/darc/wolee_edehaan_suzienoh-exploratory-ml/kevin/venv/lib/python3.10/site-packages/ray/_private/worker.py", line 2613, in get
    values, debugger_breakpoint = worker.get_objects(object_refs, timeout=timeout)
  File "/zfs/projects/darc/wolee_edehaan_suzienoh-exploratory-ml/kevin/venv/lib/python3.10/site-packages/ray/_private/worker.py", line 861, in get_objects
    raise value.as_instanceof_cause()
ray.exceptions.RayTaskError(AttributeError): [36mray::ImplicitFunc.train()[39m (pid=3498892, ip=10.112.2.40, actor_id=6e3402e7955c58233c6b3a2401000000, repr=train_fnn)
  File "/zfs/projects/darc/wolee_edehaan_suzienoh-exploratory-ml/kevin/venv/lib/python3.10/site-packages/ray/tune/trainable/trainable.py", line 331, in train
    raise skipped from exception_cause(skipped)
  File "/zfs/projects/darc/wolee_edehaan_suzienoh-exploratory-ml/kevin/venv/lib/python3.10/site-packages/ray/air/_internal/util.py", line 98, in run
    self._ret = self._target(*self._args, **self._kwargs)
  File "/zfs/projects/darc/wolee_edehaan_suzienoh-exploratory-ml/kevin/venv/lib/python3.10/site-packages/ray/tune/trainable/function_trainable.py", line 45, in <lambda>
    training_func=lambda: self._trainable_func(self.config),
  File "/zfs/projects/darc/wolee_edehaan_suzienoh-exploratory-ml/kevin/venv/lib/python3.10/site-packages/ray/tune/trainable/function_trainable.py", line 248, in _trainable_func
    output = fn()
  File "/zfs/projects/darc/wolee_edehaan_suzienoh-exploratory-ml/kevin/venv/lib/python3.10/site-packages/ray/tune/trainable/util.py", line 130, in inner
    return trainable(config, **fn_kwargs)
  File "/tmp/ray/session_2024-07-02_22-54-41_444445_3481399/runtime_resources/working_dir_files/_ray_pkg_355028f0108691b8/model_data_nn.py", line 159, in train_fnn
    loss_function = nn.MSE
AttributeError: module 'torch.nn' has no attribute 'MSE'
2024-07-02 22:55:42,751	ERROR tune_controller.py:1331 -- Trial task failed for trial train_fnn_13ce7_00016
Traceback (most recent call last):
  File "/zfs/projects/darc/wolee_edehaan_suzienoh-exploratory-ml/kevin/venv/lib/python3.10/site-packages/ray/air/execution/_internal/event_manager.py", line 110, in resolve_future
    result = ray.get(future)
  File "/zfs/projects/darc/wolee_edehaan_suzienoh-exploratory-ml/kevin/venv/lib/python3.10/site-packages/ray/_private/auto_init_hook.py", line 21, in auto_init_wrapper
    return fn(*args, **kwargs)
  File "/zfs/projects/darc/wolee_edehaan_suzienoh-exploratory-ml/kevin/venv/lib/python3.10/site-packages/ray/_private/client_mode_hook.py", line 103, in wrapper
    return func(*args, **kwargs)
  File "/zfs/projects/darc/wolee_edehaan_suzienoh-exploratory-ml/kevin/venv/lib/python3.10/site-packages/ray/_private/worker.py", line 2613, in get
    values, debugger_breakpoint = worker.get_objects(object_refs, timeout=timeout)
  File "/zfs/projects/darc/wolee_edehaan_suzienoh-exploratory-ml/kevin/venv/lib/python3.10/site-packages/ray/_private/worker.py", line 861, in get_objects
    raise value.as_instanceof_cause()
ray.exceptions.RayTaskError(AttributeError): [36mray::ImplicitFunc.train()[39m (pid=3499069, ip=10.112.2.40, actor_id=fb1c575da6b02ab51ba21b8001000000, repr=train_fnn)
  File "/zfs/projects/darc/wolee_edehaan_suzienoh-exploratory-ml/kevin/venv/lib/python3.10/site-packages/ray/tune/trainable/trainable.py", line 331, in train
    raise skipped from exception_cause(skipped)
  File "/zfs/projects/darc/wolee_edehaan_suzienoh-exploratory-ml/kevin/venv/lib/python3.10/site-packages/ray/air/_internal/util.py", line 98, in run
    self._ret = self._target(*self._args, **self._kwargs)
  File "/zfs/projects/darc/wolee_edehaan_suzienoh-exploratory-ml/kevin/venv/lib/python3.10/site-packages/ray/tune/trainable/function_trainable.py", line 45, in <lambda>
    training_func=lambda: self._trainable_func(self.config),
  File "/zfs/projects/darc/wolee_edehaan_suzienoh-exploratory-ml/kevin/venv/lib/python3.10/site-packages/ray/tune/trainable/function_trainable.py", line 248, in _trainable_func
    output = fn()
  File "/zfs/projects/darc/wolee_edehaan_suzienoh-exploratory-ml/kevin/venv/lib/python3.10/site-packages/ray/tune/trainable/util.py", line 130, in inner
    return trainable(config, **fn_kwargs)
  File "/tmp/ray/session_2024-07-02_22-54-41_444445_3481399/runtime_resources/working_dir_files/_ray_pkg_355028f0108691b8/model_data_nn.py", line 159, in train_fnn
    loss_function = nn.MSE
AttributeError: module 'torch.nn' has no attribute 'MSE'
2024-07-02 22:55:42,832	ERROR tune_controller.py:1331 -- Trial task failed for trial train_fnn_13ce7_00017
Traceback (most recent call last):
  File "/zfs/projects/darc/wolee_edehaan_suzienoh-exploratory-ml/kevin/venv/lib/python3.10/site-packages/ray/air/execution/_internal/event_manager.py", line 110, in resolve_future
    result = ray.get(future)
  File "/zfs/projects/darc/wolee_edehaan_suzienoh-exploratory-ml/kevin/venv/lib/python3.10/site-packages/ray/_private/auto_init_hook.py", line 21, in auto_init_wrapper
    return fn(*args, **kwargs)
  File "/zfs/projects/darc/wolee_edehaan_suzienoh-exploratory-ml/kevin/venv/lib/python3.10/site-packages/ray/_private/client_mode_hook.py", line 103, in wrapper
    return func(*args, **kwargs)
  File "/zfs/projects/darc/wolee_edehaan_suzienoh-exploratory-ml/kevin/venv/lib/python3.10/site-packages/ray/_private/worker.py", line 2613, in get
    values, debugger_breakpoint = worker.get_objects(object_refs, timeout=timeout)
  File "/zfs/projects/darc/wolee_edehaan_suzienoh-exploratory-ml/kevin/venv/lib/python3.10/site-packages/ray/_private/worker.py", line 861, in get_objects
    raise value.as_instanceof_cause()
ray.exceptions.RayTaskError(AttributeError): [36mray::ImplicitFunc.train()[39m (pid=3499070, ip=10.112.2.40, actor_id=5178106daaae4bcf65e5a6a901000000, repr=train_fnn)
  File "/zfs/projects/darc/wolee_edehaan_suzienoh-exploratory-ml/kevin/venv/lib/python3.10/site-packages/ray/tune/trainable/trainable.py", line 331, in train
    raise skipped from exception_cause(skipped)
  File "/zfs/projects/darc/wolee_edehaan_suzienoh-exploratory-ml/kevin/venv/lib/python3.10/site-packages/ray/air/_internal/util.py", line 98, in run
    self._ret = self._target(*self._args, **self._kwargs)
  File "/zfs/projects/darc/wolee_edehaan_suzienoh-exploratory-ml/kevin/venv/lib/python3.10/site-packages/ray/tune/trainable/function_trainable.py", line 45, in <lambda>
    training_func=lambda: self._trainable_func(self.config),
  File "/zfs/projects/darc/wolee_edehaan_suzienoh-exploratory-ml/kevin/venv/lib/python3.10/site-packages/ray/tune/trainable/function_trainable.py", line 248, in _trainable_func
    output = fn()
  File "/zfs/projects/darc/wolee_edehaan_suzienoh-exploratory-ml/kevin/venv/lib/python3.10/site-packages/ray/tune/trainable/util.py", line 130, in inner
    return trainable(config, **fn_kwargs)
  File "/tmp/ray/session_2024-07-02_22-54-41_444445_3481399/runtime_resources/working_dir_files/_ray_pkg_355028f0108691b8/model_data_nn.py", line 159, in train_fnn
    loss_function = nn.MSE
AttributeError: module 'torch.nn' has no attribute 'MSE'
2024-07-02 22:55:48,109	ERROR tune_controller.py:1331 -- Trial task failed for trial train_fnn_13ce7_00018
Traceback (most recent call last):
  File "/zfs/projects/darc/wolee_edehaan_suzienoh-exploratory-ml/kevin/venv/lib/python3.10/site-packages/ray/air/execution/_internal/event_manager.py", line 110, in resolve_future
    result = ray.get(future)
  File "/zfs/projects/darc/wolee_edehaan_suzienoh-exploratory-ml/kevin/venv/lib/python3.10/site-packages/ray/_private/auto_init_hook.py", line 21, in auto_init_wrapper
    return fn(*args, **kwargs)
  File "/zfs/projects/darc/wolee_edehaan_suzienoh-exploratory-ml/kevin/venv/lib/python3.10/site-packages/ray/_private/client_mode_hook.py", line 103, in wrapper
    return func(*args, **kwargs)
  File "/zfs/projects/darc/wolee_edehaan_suzienoh-exploratory-ml/kevin/venv/lib/python3.10/site-packages/ray/_private/worker.py", line 2613, in get
    values, debugger_breakpoint = worker.get_objects(object_refs, timeout=timeout)
  File "/zfs/projects/darc/wolee_edehaan_suzienoh-exploratory-ml/kevin/venv/lib/python3.10/site-packages/ray/_private/worker.py", line 861, in get_objects
    raise value.as_instanceof_cause()
ray.exceptions.RayTaskError(AttributeError): [36mray::ImplicitFunc.train()[39m (pid=3501517, ip=10.112.2.40, actor_id=8e6a054cc8c3f006cefd064501000000, repr=train_fnn)
  File "/zfs/projects/darc/wolee_edehaan_suzienoh-exploratory-ml/kevin/venv/lib/python3.10/site-packages/ray/tune/trainable/trainable.py", line 331, in train
    raise skipped from exception_cause(skipped)
  File "/zfs/projects/darc/wolee_edehaan_suzienoh-exploratory-ml/kevin/venv/lib/python3.10/site-packages/ray/air/_internal/util.py", line 98, in run
    self._ret = self._target(*self._args, **self._kwargs)
  File "/zfs/projects/darc/wolee_edehaan_suzienoh-exploratory-ml/kevin/venv/lib/python3.10/site-packages/ray/tune/trainable/function_trainable.py", line 45, in <lambda>
    training_func=lambda: self._trainable_func(self.config),
  File "/zfs/projects/darc/wolee_edehaan_suzienoh-exploratory-ml/kevin/venv/lib/python3.10/site-packages/ray/tune/trainable/function_trainable.py", line 248, in _trainable_func
    output = fn()
  File "/zfs/projects/darc/wolee_edehaan_suzienoh-exploratory-ml/kevin/venv/lib/python3.10/site-packages/ray/tune/trainable/util.py", line 130, in inner
    return trainable(config, **fn_kwargs)
  File "/tmp/ray/session_2024-07-02_22-54-41_444445_3481399/runtime_resources/working_dir_files/_ray_pkg_355028f0108691b8/model_data_nn.py", line 159, in train_fnn
    loss_function = nn.MSE
AttributeError: module 'torch.nn' has no attribute 'MSE'
2024-07-02 22:55:48,219	ERROR tune_controller.py:1331 -- Trial task failed for trial train_fnn_13ce7_00019
Traceback (most recent call last):
  File "/zfs/projects/darc/wolee_edehaan_suzienoh-exploratory-ml/kevin/venv/lib/python3.10/site-packages/ray/air/execution/_internal/event_manager.py", line 110, in resolve_future
    result = ray.get(future)
  File "/zfs/projects/darc/wolee_edehaan_suzienoh-exploratory-ml/kevin/venv/lib/python3.10/site-packages/ray/_private/auto_init_hook.py", line 21, in auto_init_wrapper
    return fn(*args, **kwargs)
  File "/zfs/projects/darc/wolee_edehaan_suzienoh-exploratory-ml/kevin/venv/lib/python3.10/site-packages/ray/_private/client_mode_hook.py", line 103, in wrapper
    return func(*args, **kwargs)
  File "/zfs/projects/darc/wolee_edehaan_suzienoh-exploratory-ml/kevin/venv/lib/python3.10/site-packages/ray/_private/worker.py", line 2613, in get
    values, debugger_breakpoint = worker.get_objects(object_refs, timeout=timeout)
  File "/zfs/projects/darc/wolee_edehaan_suzienoh-exploratory-ml/kevin/venv/lib/python3.10/site-packages/ray/_private/worker.py", line 861, in get_objects
    raise value.as_instanceof_cause()
ray.exceptions.RayTaskError(AttributeError): [36mray::ImplicitFunc.train()[39m (pid=3501525, ip=10.112.2.40, actor_id=727d2f5cc836b25e5356c17b01000000, repr=train_fnn)
  File "/zfs/projects/darc/wolee_edehaan_suzienoh-exploratory-ml/kevin/venv/lib/python3.10/site-packages/ray/tune/trainable/trainable.py", line 331, in train
    raise skipped from exception_cause(skipped)
  File "/zfs/projects/darc/wolee_edehaan_suzienoh-exploratory-ml/kevin/venv/lib/python3.10/site-packages/ray/air/_internal/util.py", line 98, in run
    self._ret = self._target(*self._args, **self._kwargs)
  File "/zfs/projects/darc/wolee_edehaan_suzienoh-exploratory-ml/kevin/venv/lib/python3.10/site-packages/ray/tune/trainable/function_trainable.py", line 45, in <lambda>
    training_func=lambda: self._trainable_func(self.config),
  File "/zfs/projects/darc/wolee_edehaan_suzienoh-exploratory-ml/kevin/venv/lib/python3.10/site-packages/ray/tune/trainable/function_trainable.py", line 248, in _trainable_func
    output = fn()
  File "/zfs/projects/darc/wolee_edehaan_suzienoh-exploratory-ml/kevin/venv/lib/python3.10/site-packages/ray/tune/trainable/util.py", line 130, in inner
    return trainable(config, **fn_kwargs)
  File "/tmp/ray/session_2024-07-02_22-54-41_444445_3481399/runtime_resources/working_dir_files/_ray_pkg_355028f0108691b8/model_data_nn.py", line 159, in train_fnn
    loss_function = nn.MSE
AttributeError: module 'torch.nn' has no attribute 'MSE'
2024-07-02 22:55:53,441	ERROR tune_controller.py:1331 -- Trial task failed for trial train_fnn_13ce7_00021
Traceback (most recent call last):
  File "/zfs/projects/darc/wolee_edehaan_suzienoh-exploratory-ml/kevin/venv/lib/python3.10/site-packages/ray/air/execution/_internal/event_manager.py", line 110, in resolve_future
    result = ray.get(future)
  File "/zfs/projects/darc/wolee_edehaan_suzienoh-exploratory-ml/kevin/venv/lib/python3.10/site-packages/ray/_private/auto_init_hook.py", line 21, in auto_init_wrapper
    return fn(*args, **kwargs)
  File "/zfs/projects/darc/wolee_edehaan_suzienoh-exploratory-ml/kevin/venv/lib/python3.10/site-packages/ray/_private/client_mode_hook.py", line 103, in wrapper
    return func(*args, **kwargs)
  File "/zfs/projects/darc/wolee_edehaan_suzienoh-exploratory-ml/kevin/venv/lib/python3.10/site-packages/ray/_private/worker.py", line 2613, in get
    values, debugger_breakpoint = worker.get_objects(object_refs, timeout=timeout)
  File "/zfs/projects/darc/wolee_edehaan_suzienoh-exploratory-ml/kevin/venv/lib/python3.10/site-packages/ray/_private/worker.py", line 861, in get_objects
    raise value.as_instanceof_cause()
ray.exceptions.RayTaskError(AttributeError): [36mray::ImplicitFunc.train()[39m (pid=3505130, ip=10.112.2.40, actor_id=7697b13204cabd05c36d85be01000000, repr=train_fnn)
  File "/zfs/projects/darc/wolee_edehaan_suzienoh-exploratory-ml/kevin/venv/lib/python3.10/site-packages/ray/tune/trainable/trainable.py", line 331, in train
    raise skipped from exception_cause(skipped)
  File "/zfs/projects/darc/wolee_edehaan_suzienoh-exploratory-ml/kevin/venv/lib/python3.10/site-packages/ray/air/_internal/util.py", line 98, in run
    self._ret = self._target(*self._args, **self._kwargs)
  File "/zfs/projects/darc/wolee_edehaan_suzienoh-exploratory-ml/kevin/venv/lib/python3.10/site-packages/ray/tune/trainable/function_trainable.py", line 45, in <lambda>
    training_func=lambda: self._trainable_func(self.config),
  File "/zfs/projects/darc/wolee_edehaan_suzienoh-exploratory-ml/kevin/venv/lib/python3.10/site-packages/ray/tune/trainable/function_trainable.py", line 248, in _trainable_func
    output = fn()
  File "/zfs/projects/darc/wolee_edehaan_suzienoh-exploratory-ml/kevin/venv/lib/python3.10/site-packages/ray/tune/trainable/util.py", line 130, in inner
    return trainable(config, **fn_kwargs)
  File "/tmp/ray/session_2024-07-02_22-54-41_444445_3481399/runtime_resources/working_dir_files/_ray_pkg_355028f0108691b8/model_data_nn.py", line 159, in train_fnn
    loss_function = nn.MSE
AttributeError: module 'torch.nn' has no attribute 'MSE'
2024-07-02 22:55:54,876	ERROR tune_controller.py:1331 -- Trial task failed for trial train_fnn_13ce7_00020
Traceback (most recent call last):
  File "/zfs/projects/darc/wolee_edehaan_suzienoh-exploratory-ml/kevin/venv/lib/python3.10/site-packages/ray/air/execution/_internal/event_manager.py", line 110, in resolve_future
    result = ray.get(future)
  File "/zfs/projects/darc/wolee_edehaan_suzienoh-exploratory-ml/kevin/venv/lib/python3.10/site-packages/ray/_private/auto_init_hook.py", line 21, in auto_init_wrapper
    return fn(*args, **kwargs)
  File "/zfs/projects/darc/wolee_edehaan_suzienoh-exploratory-ml/kevin/venv/lib/python3.10/site-packages/ray/_private/client_mode_hook.py", line 103, in wrapper
    return func(*args, **kwargs)
  File "/zfs/projects/darc/wolee_edehaan_suzienoh-exploratory-ml/kevin/venv/lib/python3.10/site-packages/ray/_private/worker.py", line 2613, in get
    values, debugger_breakpoint = worker.get_objects(object_refs, timeout=timeout)
  File "/zfs/projects/darc/wolee_edehaan_suzienoh-exploratory-ml/kevin/venv/lib/python3.10/site-packages/ray/_private/worker.py", line 861, in get_objects
    raise value.as_instanceof_cause()
ray.exceptions.RayTaskError(AttributeError): [36mray::ImplicitFunc.train()[39m (pid=3505129, ip=10.112.2.40, actor_id=80d5fab075481d432acb1e2a01000000, repr=train_fnn)
  File "/zfs/projects/darc/wolee_edehaan_suzienoh-exploratory-ml/kevin/venv/lib/python3.10/site-packages/ray/tune/trainable/trainable.py", line 331, in train
    raise skipped from exception_cause(skipped)
  File "/zfs/projects/darc/wolee_edehaan_suzienoh-exploratory-ml/kevin/venv/lib/python3.10/site-packages/ray/air/_internal/util.py", line 98, in run
    self._ret = self._target(*self._args, **self._kwargs)
  File "/zfs/projects/darc/wolee_edehaan_suzienoh-exploratory-ml/kevin/venv/lib/python3.10/site-packages/ray/tune/trainable/function_trainable.py", line 45, in <lambda>
    training_func=lambda: self._trainable_func(self.config),
  File "/zfs/projects/darc/wolee_edehaan_suzienoh-exploratory-ml/kevin/venv/lib/python3.10/site-packages/ray/tune/trainable/function_trainable.py", line 248, in _trainable_func
    output = fn()
  File "/zfs/projects/darc/wolee_edehaan_suzienoh-exploratory-ml/kevin/venv/lib/python3.10/site-packages/ray/tune/trainable/util.py", line 130, in inner
    return trainable(config, **fn_kwargs)
  File "/tmp/ray/session_2024-07-02_22-54-41_444445_3481399/runtime_resources/working_dir_files/_ray_pkg_355028f0108691b8/model_data_nn.py", line 159, in train_fnn
    loss_function = nn.MSE
AttributeError: module 'torch.nn' has no attribute 'MSE'
2024-07-02 22:55:59,322	ERROR tune_controller.py:1331 -- Trial task failed for trial train_fnn_13ce7_00022
Traceback (most recent call last):
  File "/zfs/projects/darc/wolee_edehaan_suzienoh-exploratory-ml/kevin/venv/lib/python3.10/site-packages/ray/air/execution/_internal/event_manager.py", line 110, in resolve_future
    result = ray.get(future)
  File "/zfs/projects/darc/wolee_edehaan_suzienoh-exploratory-ml/kevin/venv/lib/python3.10/site-packages/ray/_private/auto_init_hook.py", line 21, in auto_init_wrapper
    return fn(*args, **kwargs)
  File "/zfs/projects/darc/wolee_edehaan_suzienoh-exploratory-ml/kevin/venv/lib/python3.10/site-packages/ray/_private/client_mode_hook.py", line 103, in wrapper
    return func(*args, **kwargs)
  File "/zfs/projects/darc/wolee_edehaan_suzienoh-exploratory-ml/kevin/venv/lib/python3.10/site-packages/ray/_private/worker.py", line 2613, in get
    values, debugger_breakpoint = worker.get_objects(object_refs, timeout=timeout)
  File "/zfs/projects/darc/wolee_edehaan_suzienoh-exploratory-ml/kevin/venv/lib/python3.10/site-packages/ray/_private/worker.py", line 861, in get_objects
    raise value.as_instanceof_cause()
ray.exceptions.RayTaskError(AttributeError): [36mray::ImplicitFunc.train()[39m (pid=3505272, ip=10.112.2.40, actor_id=afa6b2e5b7ecda8746a5059801000000, repr=train_fnn)
  File "/zfs/projects/darc/wolee_edehaan_suzienoh-exploratory-ml/kevin/venv/lib/python3.10/site-packages/ray/tune/trainable/trainable.py", line 331, in train
    raise skipped from exception_cause(skipped)
  File "/zfs/projects/darc/wolee_edehaan_suzienoh-exploratory-ml/kevin/venv/lib/python3.10/site-packages/ray/air/_internal/util.py", line 98, in run
    self._ret = self._target(*self._args, **self._kwargs)
  File "/zfs/projects/darc/wolee_edehaan_suzienoh-exploratory-ml/kevin/venv/lib/python3.10/site-packages/ray/tune/trainable/function_trainable.py", line 45, in <lambda>
    training_func=lambda: self._trainable_func(self.config),
  File "/zfs/projects/darc/wolee_edehaan_suzienoh-exploratory-ml/kevin/venv/lib/python3.10/site-packages/ray/tune/trainable/function_trainable.py", line 248, in _trainable_func
    output = fn()
  File "/zfs/projects/darc/wolee_edehaan_suzienoh-exploratory-ml/kevin/venv/lib/python3.10/site-packages/ray/tune/trainable/util.py", line 130, in inner
    return trainable(config, **fn_kwargs)
  File "/tmp/ray/session_2024-07-02_22-54-41_444445_3481399/runtime_resources/working_dir_files/_ray_pkg_355028f0108691b8/model_data_nn.py", line 159, in train_fnn
    loss_function = nn.MSE
AttributeError: module 'torch.nn' has no attribute 'MSE'
2024-07-02 22:56:01,535	ERROR tune_controller.py:1331 -- Trial task failed for trial train_fnn_13ce7_00023
Traceback (most recent call last):
  File "/zfs/projects/darc/wolee_edehaan_suzienoh-exploratory-ml/kevin/venv/lib/python3.10/site-packages/ray/air/execution/_internal/event_manager.py", line 110, in resolve_future
    result = ray.get(future)
  File "/zfs/projects/darc/wolee_edehaan_suzienoh-exploratory-ml/kevin/venv/lib/python3.10/site-packages/ray/_private/auto_init_hook.py", line 21, in auto_init_wrapper
    return fn(*args, **kwargs)
  File "/zfs/projects/darc/wolee_edehaan_suzienoh-exploratory-ml/kevin/venv/lib/python3.10/site-packages/ray/_private/client_mode_hook.py", line 103, in wrapper
    return func(*args, **kwargs)
  File "/zfs/projects/darc/wolee_edehaan_suzienoh-exploratory-ml/kevin/venv/lib/python3.10/site-packages/ray/_private/worker.py", line 2613, in get
    values, debugger_breakpoint = worker.get_objects(object_refs, timeout=timeout)
  File "/zfs/projects/darc/wolee_edehaan_suzienoh-exploratory-ml/kevin/venv/lib/python3.10/site-packages/ray/_private/worker.py", line 861, in get_objects
    raise value.as_instanceof_cause()
ray.exceptions.RayTaskError(AttributeError): [36mray::ImplicitFunc.train()[39m (pid=3505356, ip=10.112.2.40, actor_id=e270fff8664d4d1c66cf8b0a01000000, repr=train_fnn)
  File "/zfs/projects/darc/wolee_edehaan_suzienoh-exploratory-ml/kevin/venv/lib/python3.10/site-packages/ray/tune/trainable/trainable.py", line 331, in train
    raise skipped from exception_cause(skipped)
  File "/zfs/projects/darc/wolee_edehaan_suzienoh-exploratory-ml/kevin/venv/lib/python3.10/site-packages/ray/air/_internal/util.py", line 98, in run
    self._ret = self._target(*self._args, **self._kwargs)
  File "/zfs/projects/darc/wolee_edehaan_suzienoh-exploratory-ml/kevin/venv/lib/python3.10/site-packages/ray/tune/trainable/function_trainable.py", line 45, in <lambda>
    training_func=lambda: self._trainable_func(self.config),
  File "/zfs/projects/darc/wolee_edehaan_suzienoh-exploratory-ml/kevin/venv/lib/python3.10/site-packages/ray/tune/trainable/function_trainable.py", line 248, in _trainable_func
    output = fn()
  File "/zfs/projects/darc/wolee_edehaan_suzienoh-exploratory-ml/kevin/venv/lib/python3.10/site-packages/ray/tune/trainable/util.py", line 130, in inner
    return trainable(config, **fn_kwargs)
  File "/tmp/ray/session_2024-07-02_22-54-41_444445_3481399/runtime_resources/working_dir_files/_ray_pkg_355028f0108691b8/model_data_nn.py", line 159, in train_fnn
    loss_function = nn.MSE
AttributeError: module 'torch.nn' has no attribute 'MSE'
2024-07-02 22:56:05,418	ERROR tune_controller.py:1331 -- Trial task failed for trial train_fnn_13ce7_00024
Traceback (most recent call last):
  File "/zfs/projects/darc/wolee_edehaan_suzienoh-exploratory-ml/kevin/venv/lib/python3.10/site-packages/ray/air/execution/_internal/event_manager.py", line 110, in resolve_future
    result = ray.get(future)
  File "/zfs/projects/darc/wolee_edehaan_suzienoh-exploratory-ml/kevin/venv/lib/python3.10/site-packages/ray/_private/auto_init_hook.py", line 21, in auto_init_wrapper
    return fn(*args, **kwargs)
  File "/zfs/projects/darc/wolee_edehaan_suzienoh-exploratory-ml/kevin/venv/lib/python3.10/site-packages/ray/_private/client_mode_hook.py", line 103, in wrapper
    return func(*args, **kwargs)
  File "/zfs/projects/darc/wolee_edehaan_suzienoh-exploratory-ml/kevin/venv/lib/python3.10/site-packages/ray/_private/worker.py", line 2613, in get
    values, debugger_breakpoint = worker.get_objects(object_refs, timeout=timeout)
  File "/zfs/projects/darc/wolee_edehaan_suzienoh-exploratory-ml/kevin/venv/lib/python3.10/site-packages/ray/_private/worker.py", line 861, in get_objects
    raise value.as_instanceof_cause()
ray.exceptions.RayTaskError(AttributeError): [36mray::ImplicitFunc.train()[39m (pid=3505437, ip=10.112.2.40, actor_id=c64a6526dc0c4e630738a5dd01000000, repr=train_fnn)
  File "/zfs/projects/darc/wolee_edehaan_suzienoh-exploratory-ml/kevin/venv/lib/python3.10/site-packages/ray/tune/trainable/trainable.py", line 331, in train
    raise skipped from exception_cause(skipped)
  File "/zfs/projects/darc/wolee_edehaan_suzienoh-exploratory-ml/kevin/venv/lib/python3.10/site-packages/ray/air/_internal/util.py", line 98, in run
    self._ret = self._target(*self._args, **self._kwargs)
  File "/zfs/projects/darc/wolee_edehaan_suzienoh-exploratory-ml/kevin/venv/lib/python3.10/site-packages/ray/tune/trainable/function_trainable.py", line 45, in <lambda>
    training_func=lambda: self._trainable_func(self.config),
  File "/zfs/projects/darc/wolee_edehaan_suzienoh-exploratory-ml/kevin/venv/lib/python3.10/site-packages/ray/tune/trainable/function_trainable.py", line 248, in _trainable_func
    output = fn()
  File "/zfs/projects/darc/wolee_edehaan_suzienoh-exploratory-ml/kevin/venv/lib/python3.10/site-packages/ray/tune/trainable/util.py", line 130, in inner
    return trainable(config, **fn_kwargs)
  File "/tmp/ray/session_2024-07-02_22-54-41_444445_3481399/runtime_resources/working_dir_files/_ray_pkg_355028f0108691b8/model_data_nn.py", line 159, in train_fnn
    loss_function = nn.MSE
AttributeError: module 'torch.nn' has no attribute 'MSE'
2024-07-02 22:56:07,453	ERROR tune_controller.py:1331 -- Trial task failed for trial train_fnn_13ce7_00025
Traceback (most recent call last):
  File "/zfs/projects/darc/wolee_edehaan_suzienoh-exploratory-ml/kevin/venv/lib/python3.10/site-packages/ray/air/execution/_internal/event_manager.py", line 110, in resolve_future
    result = ray.get(future)
  File "/zfs/projects/darc/wolee_edehaan_suzienoh-exploratory-ml/kevin/venv/lib/python3.10/site-packages/ray/_private/auto_init_hook.py", line 21, in auto_init_wrapper
    return fn(*args, **kwargs)
  File "/zfs/projects/darc/wolee_edehaan_suzienoh-exploratory-ml/kevin/venv/lib/python3.10/site-packages/ray/_private/client_mode_hook.py", line 103, in wrapper
    return func(*args, **kwargs)
  File "/zfs/projects/darc/wolee_edehaan_suzienoh-exploratory-ml/kevin/venv/lib/python3.10/site-packages/ray/_private/worker.py", line 2613, in get
    values, debugger_breakpoint = worker.get_objects(object_refs, timeout=timeout)
  File "/zfs/projects/darc/wolee_edehaan_suzienoh-exploratory-ml/kevin/venv/lib/python3.10/site-packages/ray/_private/worker.py", line 861, in get_objects
    raise value.as_instanceof_cause()
ray.exceptions.RayTaskError(AttributeError): [36mray::ImplicitFunc.train()[39m (pid=3505518, ip=10.112.2.40, actor_id=ce595df54dd0cd31a19c648601000000, repr=train_fnn)
  File "/zfs/projects/darc/wolee_edehaan_suzienoh-exploratory-ml/kevin/venv/lib/python3.10/site-packages/ray/tune/trainable/trainable.py", line 331, in train
    raise skipped from exception_cause(skipped)
  File "/zfs/projects/darc/wolee_edehaan_suzienoh-exploratory-ml/kevin/venv/lib/python3.10/site-packages/ray/air/_internal/util.py", line 98, in run
    self._ret = self._target(*self._args, **self._kwargs)
  File "/zfs/projects/darc/wolee_edehaan_suzienoh-exploratory-ml/kevin/venv/lib/python3.10/site-packages/ray/tune/trainable/function_trainable.py", line 45, in <lambda>
    training_func=lambda: self._trainable_func(self.config),
  File "/zfs/projects/darc/wolee_edehaan_suzienoh-exploratory-ml/kevin/venv/lib/python3.10/site-packages/ray/tune/trainable/function_trainable.py", line 248, in _trainable_func
    output = fn()
  File "/zfs/projects/darc/wolee_edehaan_suzienoh-exploratory-ml/kevin/venv/lib/python3.10/site-packages/ray/tune/trainable/util.py", line 130, in inner
    return trainable(config, **fn_kwargs)
  File "/tmp/ray/session_2024-07-02_22-54-41_444445_3481399/runtime_resources/working_dir_files/_ray_pkg_355028f0108691b8/model_data_nn.py", line 159, in train_fnn
    loss_function = nn.MSE
AttributeError: module 'torch.nn' has no attribute 'MSE'
2024-07-02 22:56:11,021	ERROR tune_controller.py:1331 -- Trial task failed for trial train_fnn_13ce7_00026
Traceback (most recent call last):
  File "/zfs/projects/darc/wolee_edehaan_suzienoh-exploratory-ml/kevin/venv/lib/python3.10/site-packages/ray/air/execution/_internal/event_manager.py", line 110, in resolve_future
    result = ray.get(future)
  File "/zfs/projects/darc/wolee_edehaan_suzienoh-exploratory-ml/kevin/venv/lib/python3.10/site-packages/ray/_private/auto_init_hook.py", line 21, in auto_init_wrapper
    return fn(*args, **kwargs)
  File "/zfs/projects/darc/wolee_edehaan_suzienoh-exploratory-ml/kevin/venv/lib/python3.10/site-packages/ray/_private/client_mode_hook.py", line 103, in wrapper
    return func(*args, **kwargs)
  File "/zfs/projects/darc/wolee_edehaan_suzienoh-exploratory-ml/kevin/venv/lib/python3.10/site-packages/ray/_private/worker.py", line 2613, in get
    values, debugger_breakpoint = worker.get_objects(object_refs, timeout=timeout)
  File "/zfs/projects/darc/wolee_edehaan_suzienoh-exploratory-ml/kevin/venv/lib/python3.10/site-packages/ray/_private/worker.py", line 861, in get_objects
    raise value.as_instanceof_cause()
ray.exceptions.RayTaskError(AttributeError): [36mray::ImplicitFunc.train()[39m (pid=3505598, ip=10.112.2.40, actor_id=faf61b1850dc437c7569306001000000, repr=train_fnn)
  File "/zfs/projects/darc/wolee_edehaan_suzienoh-exploratory-ml/kevin/venv/lib/python3.10/site-packages/ray/tune/trainable/trainable.py", line 331, in train
    raise skipped from exception_cause(skipped)
  File "/zfs/projects/darc/wolee_edehaan_suzienoh-exploratory-ml/kevin/venv/lib/python3.10/site-packages/ray/air/_internal/util.py", line 98, in run
    self._ret = self._target(*self._args, **self._kwargs)
  File "/zfs/projects/darc/wolee_edehaan_suzienoh-exploratory-ml/kevin/venv/lib/python3.10/site-packages/ray/tune/trainable/function_trainable.py", line 45, in <lambda>
    training_func=lambda: self._trainable_func(self.config),
  File "/zfs/projects/darc/wolee_edehaan_suzienoh-exploratory-ml/kevin/venv/lib/python3.10/site-packages/ray/tune/trainable/function_trainable.py", line 248, in _trainable_func
    output = fn()
  File "/zfs/projects/darc/wolee_edehaan_suzienoh-exploratory-ml/kevin/venv/lib/python3.10/site-packages/ray/tune/trainable/util.py", line 130, in inner
    return trainable(config, **fn_kwargs)
  File "/tmp/ray/session_2024-07-02_22-54-41_444445_3481399/runtime_resources/working_dir_files/_ray_pkg_355028f0108691b8/model_data_nn.py", line 159, in train_fnn
    loss_function = nn.MSE
AttributeError: module 'torch.nn' has no attribute 'MSE'
2024-07-02 22:56:12,815	ERROR tune_controller.py:1331 -- Trial task failed for trial train_fnn_13ce7_00027
Traceback (most recent call last):
  File "/zfs/projects/darc/wolee_edehaan_suzienoh-exploratory-ml/kevin/venv/lib/python3.10/site-packages/ray/air/execution/_internal/event_manager.py", line 110, in resolve_future
    result = ray.get(future)
  File "/zfs/projects/darc/wolee_edehaan_suzienoh-exploratory-ml/kevin/venv/lib/python3.10/site-packages/ray/_private/auto_init_hook.py", line 21, in auto_init_wrapper
    return fn(*args, **kwargs)
  File "/zfs/projects/darc/wolee_edehaan_suzienoh-exploratory-ml/kevin/venv/lib/python3.10/site-packages/ray/_private/client_mode_hook.py", line 103, in wrapper
    return func(*args, **kwargs)
  File "/zfs/projects/darc/wolee_edehaan_suzienoh-exploratory-ml/kevin/venv/lib/python3.10/site-packages/ray/_private/worker.py", line 2613, in get
    values, debugger_breakpoint = worker.get_objects(object_refs, timeout=timeout)
  File "/zfs/projects/darc/wolee_edehaan_suzienoh-exploratory-ml/kevin/venv/lib/python3.10/site-packages/ray/_private/worker.py", line 861, in get_objects
    raise value.as_instanceof_cause()
ray.exceptions.RayTaskError(AttributeError): [36mray::ImplicitFunc.train()[39m (pid=3505679, ip=10.112.2.40, actor_id=20e8d4b0f11813ab905c7d5b01000000, repr=train_fnn)
  File "/zfs/projects/darc/wolee_edehaan_suzienoh-exploratory-ml/kevin/venv/lib/python3.10/site-packages/ray/tune/trainable/trainable.py", line 331, in train
    raise skipped from exception_cause(skipped)
  File "/zfs/projects/darc/wolee_edehaan_suzienoh-exploratory-ml/kevin/venv/lib/python3.10/site-packages/ray/air/_internal/util.py", line 98, in run
    self._ret = self._target(*self._args, **self._kwargs)
  File "/zfs/projects/darc/wolee_edehaan_suzienoh-exploratory-ml/kevin/venv/lib/python3.10/site-packages/ray/tune/trainable/function_trainable.py", line 45, in <lambda>
    training_func=lambda: self._trainable_func(self.config),
  File "/zfs/projects/darc/wolee_edehaan_suzienoh-exploratory-ml/kevin/venv/lib/python3.10/site-packages/ray/tune/trainable/function_trainable.py", line 248, in _trainable_func
    output = fn()
  File "/zfs/projects/darc/wolee_edehaan_suzienoh-exploratory-ml/kevin/venv/lib/python3.10/site-packages/ray/tune/trainable/util.py", line 130, in inner
    return trainable(config, **fn_kwargs)
  File "/tmp/ray/session_2024-07-02_22-54-41_444445_3481399/runtime_resources/working_dir_files/_ray_pkg_355028f0108691b8/model_data_nn.py", line 159, in train_fnn
    loss_function = nn.MSE
AttributeError: module 'torch.nn' has no attribute 'MSE'
2024-07-02 22:56:16,829	ERROR tune_controller.py:1331 -- Trial task failed for trial train_fnn_13ce7_00028
Traceback (most recent call last):
  File "/zfs/projects/darc/wolee_edehaan_suzienoh-exploratory-ml/kevin/venv/lib/python3.10/site-packages/ray/air/execution/_internal/event_manager.py", line 110, in resolve_future
    result = ray.get(future)
  File "/zfs/projects/darc/wolee_edehaan_suzienoh-exploratory-ml/kevin/venv/lib/python3.10/site-packages/ray/_private/auto_init_hook.py", line 21, in auto_init_wrapper
    return fn(*args, **kwargs)
  File "/zfs/projects/darc/wolee_edehaan_suzienoh-exploratory-ml/kevin/venv/lib/python3.10/site-packages/ray/_private/client_mode_hook.py", line 103, in wrapper
    return func(*args, **kwargs)
  File "/zfs/projects/darc/wolee_edehaan_suzienoh-exploratory-ml/kevin/venv/lib/python3.10/site-packages/ray/_private/worker.py", line 2613, in get
    values, debugger_breakpoint = worker.get_objects(object_refs, timeout=timeout)
  File "/zfs/projects/darc/wolee_edehaan_suzienoh-exploratory-ml/kevin/venv/lib/python3.10/site-packages/ray/_private/worker.py", line 861, in get_objects
    raise value.as_instanceof_cause()
ray.exceptions.RayTaskError(AttributeError): [36mray::ImplicitFunc.train()[39m (pid=3505760, ip=10.112.2.40, actor_id=0c908ede1bd0b212bc1332bb01000000, repr=train_fnn)
  File "/zfs/projects/darc/wolee_edehaan_suzienoh-exploratory-ml/kevin/venv/lib/python3.10/site-packages/ray/tune/trainable/trainable.py", line 331, in train
    raise skipped from exception_cause(skipped)
  File "/zfs/projects/darc/wolee_edehaan_suzienoh-exploratory-ml/kevin/venv/lib/python3.10/site-packages/ray/air/_internal/util.py", line 98, in run
    self._ret = self._target(*self._args, **self._kwargs)
  File "/zfs/projects/darc/wolee_edehaan_suzienoh-exploratory-ml/kevin/venv/lib/python3.10/site-packages/ray/tune/trainable/function_trainable.py", line 45, in <lambda>
    training_func=lambda: self._trainable_func(self.config),
  File "/zfs/projects/darc/wolee_edehaan_suzienoh-exploratory-ml/kevin/venv/lib/python3.10/site-packages/ray/tune/trainable/function_trainable.py", line 248, in _trainable_func
    output = fn()
  File "/zfs/projects/darc/wolee_edehaan_suzienoh-exploratory-ml/kevin/venv/lib/python3.10/site-packages/ray/tune/trainable/util.py", line 130, in inner
    return trainable(config, **fn_kwargs)
  File "/tmp/ray/session_2024-07-02_22-54-41_444445_3481399/runtime_resources/working_dir_files/_ray_pkg_355028f0108691b8/model_data_nn.py", line 159, in train_fnn
    loss_function = nn.MSE
AttributeError: module 'torch.nn' has no attribute 'MSE'
2024-07-02 22:56:18,749	ERROR tune_controller.py:1331 -- Trial task failed for trial train_fnn_13ce7_00029
Traceback (most recent call last):
  File "/zfs/projects/darc/wolee_edehaan_suzienoh-exploratory-ml/kevin/venv/lib/python3.10/site-packages/ray/air/execution/_internal/event_manager.py", line 110, in resolve_future
    result = ray.get(future)
  File "/zfs/projects/darc/wolee_edehaan_suzienoh-exploratory-ml/kevin/venv/lib/python3.10/site-packages/ray/_private/auto_init_hook.py", line 21, in auto_init_wrapper
    return fn(*args, **kwargs)
  File "/zfs/projects/darc/wolee_edehaan_suzienoh-exploratory-ml/kevin/venv/lib/python3.10/site-packages/ray/_private/client_mode_hook.py", line 103, in wrapper
    return func(*args, **kwargs)
  File "/zfs/projects/darc/wolee_edehaan_suzienoh-exploratory-ml/kevin/venv/lib/python3.10/site-packages/ray/_private/worker.py", line 2613, in get
    values, debugger_breakpoint = worker.get_objects(object_refs, timeout=timeout)
  File "/zfs/projects/darc/wolee_edehaan_suzienoh-exploratory-ml/kevin/venv/lib/python3.10/site-packages/ray/_private/worker.py", line 861, in get_objects
    raise value.as_instanceof_cause()
ray.exceptions.RayTaskError(AttributeError): [36mray::ImplicitFunc.train()[39m (pid=3505840, ip=10.112.2.40, actor_id=650f2bdfab45e0b26ee8c74901000000, repr=train_fnn)
  File "/zfs/projects/darc/wolee_edehaan_suzienoh-exploratory-ml/kevin/venv/lib/python3.10/site-packages/ray/tune/trainable/trainable.py", line 331, in train
    raise skipped from exception_cause(skipped)
  File "/zfs/projects/darc/wolee_edehaan_suzienoh-exploratory-ml/kevin/venv/lib/python3.10/site-packages/ray/air/_internal/util.py", line 98, in run
    self._ret = self._target(*self._args, **self._kwargs)
  File "/zfs/projects/darc/wolee_edehaan_suzienoh-exploratory-ml/kevin/venv/lib/python3.10/site-packages/ray/tune/trainable/function_trainable.py", line 45, in <lambda>
    training_func=lambda: self._trainable_func(self.config),
  File "/zfs/projects/darc/wolee_edehaan_suzienoh-exploratory-ml/kevin/venv/lib/python3.10/site-packages/ray/tune/trainable/function_trainable.py", line 248, in _trainable_func
    output = fn()
  File "/zfs/projects/darc/wolee_edehaan_suzienoh-exploratory-ml/kevin/venv/lib/python3.10/site-packages/ray/tune/trainable/util.py", line 130, in inner
    return trainable(config, **fn_kwargs)
  File "/tmp/ray/session_2024-07-02_22-54-41_444445_3481399/runtime_resources/working_dir_files/_ray_pkg_355028f0108691b8/model_data_nn.py", line 159, in train_fnn
    loss_function = nn.MSE
AttributeError: module 'torch.nn' has no attribute 'MSE'
2024-07-02 22:56:22,947	ERROR tune_controller.py:1331 -- Trial task failed for trial train_fnn_13ce7_00030
Traceback (most recent call last):
  File "/zfs/projects/darc/wolee_edehaan_suzienoh-exploratory-ml/kevin/venv/lib/python3.10/site-packages/ray/air/execution/_internal/event_manager.py", line 110, in resolve_future
    result = ray.get(future)
  File "/zfs/projects/darc/wolee_edehaan_suzienoh-exploratory-ml/kevin/venv/lib/python3.10/site-packages/ray/_private/auto_init_hook.py", line 21, in auto_init_wrapper
    return fn(*args, **kwargs)
  File "/zfs/projects/darc/wolee_edehaan_suzienoh-exploratory-ml/kevin/venv/lib/python3.10/site-packages/ray/_private/client_mode_hook.py", line 103, in wrapper
    return func(*args, **kwargs)
  File "/zfs/projects/darc/wolee_edehaan_suzienoh-exploratory-ml/kevin/venv/lib/python3.10/site-packages/ray/_private/worker.py", line 2613, in get
    values, debugger_breakpoint = worker.get_objects(object_refs, timeout=timeout)
  File "/zfs/projects/darc/wolee_edehaan_suzienoh-exploratory-ml/kevin/venv/lib/python3.10/site-packages/ray/_private/worker.py", line 861, in get_objects
    raise value.as_instanceof_cause()
ray.exceptions.RayTaskError(AttributeError): [36mray::ImplicitFunc.train()[39m (pid=3505921, ip=10.112.2.40, actor_id=02ba57490a9c7f10cb12fc5f01000000, repr=train_fnn)
  File "/zfs/projects/darc/wolee_edehaan_suzienoh-exploratory-ml/kevin/venv/lib/python3.10/site-packages/ray/tune/trainable/trainable.py", line 331, in train
    raise skipped from exception_cause(skipped)
  File "/zfs/projects/darc/wolee_edehaan_suzienoh-exploratory-ml/kevin/venv/lib/python3.10/site-packages/ray/air/_internal/util.py", line 98, in run
    self._ret = self._target(*self._args, **self._kwargs)
  File "/zfs/projects/darc/wolee_edehaan_suzienoh-exploratory-ml/kevin/venv/lib/python3.10/site-packages/ray/tune/trainable/function_trainable.py", line 45, in <lambda>
    training_func=lambda: self._trainable_func(self.config),
  File "/zfs/projects/darc/wolee_edehaan_suzienoh-exploratory-ml/kevin/venv/lib/python3.10/site-packages/ray/tune/trainable/function_trainable.py", line 248, in _trainable_func
    output = fn()
  File "/zfs/projects/darc/wolee_edehaan_suzienoh-exploratory-ml/kevin/venv/lib/python3.10/site-packages/ray/tune/trainable/util.py", line 130, in inner
    return trainable(config, **fn_kwargs)
  File "/tmp/ray/session_2024-07-02_22-54-41_444445_3481399/runtime_resources/working_dir_files/_ray_pkg_355028f0108691b8/model_data_nn.py", line 159, in train_fnn
    loss_function = nn.MSE
AttributeError: module 'torch.nn' has no attribute 'MSE'
2024-07-02 22:56:25,041	ERROR tune_controller.py:1331 -- Trial task failed for trial train_fnn_13ce7_00031
Traceback (most recent call last):
  File "/zfs/projects/darc/wolee_edehaan_suzienoh-exploratory-ml/kevin/venv/lib/python3.10/site-packages/ray/air/execution/_internal/event_manager.py", line 110, in resolve_future
    result = ray.get(future)
  File "/zfs/projects/darc/wolee_edehaan_suzienoh-exploratory-ml/kevin/venv/lib/python3.10/site-packages/ray/_private/auto_init_hook.py", line 21, in auto_init_wrapper
    return fn(*args, **kwargs)
  File "/zfs/projects/darc/wolee_edehaan_suzienoh-exploratory-ml/kevin/venv/lib/python3.10/site-packages/ray/_private/client_mode_hook.py", line 103, in wrapper
    return func(*args, **kwargs)
  File "/zfs/projects/darc/wolee_edehaan_suzienoh-exploratory-ml/kevin/venv/lib/python3.10/site-packages/ray/_private/worker.py", line 2613, in get
    values, debugger_breakpoint = worker.get_objects(object_refs, timeout=timeout)
  File "/zfs/projects/darc/wolee_edehaan_suzienoh-exploratory-ml/kevin/venv/lib/python3.10/site-packages/ray/_private/worker.py", line 861, in get_objects
    raise value.as_instanceof_cause()
ray.exceptions.RayTaskError(AttributeError): [36mray::ImplicitFunc.train()[39m (pid=3506000, ip=10.112.2.40, actor_id=dbb67bc94a39727f681e613701000000, repr=train_fnn)
  File "/zfs/projects/darc/wolee_edehaan_suzienoh-exploratory-ml/kevin/venv/lib/python3.10/site-packages/ray/tune/trainable/trainable.py", line 331, in train
    raise skipped from exception_cause(skipped)
  File "/zfs/projects/darc/wolee_edehaan_suzienoh-exploratory-ml/kevin/venv/lib/python3.10/site-packages/ray/air/_internal/util.py", line 98, in run
    self._ret = self._target(*self._args, **self._kwargs)
  File "/zfs/projects/darc/wolee_edehaan_suzienoh-exploratory-ml/kevin/venv/lib/python3.10/site-packages/ray/tune/trainable/function_trainable.py", line 45, in <lambda>
    training_func=lambda: self._trainable_func(self.config),
  File "/zfs/projects/darc/wolee_edehaan_suzienoh-exploratory-ml/kevin/venv/lib/python3.10/site-packages/ray/tune/trainable/function_trainable.py", line 248, in _trainable_func
    output = fn()
  File "/zfs/projects/darc/wolee_edehaan_suzienoh-exploratory-ml/kevin/venv/lib/python3.10/site-packages/ray/tune/trainable/util.py", line 130, in inner
    return trainable(config, **fn_kwargs)
  File "/tmp/ray/session_2024-07-02_22-54-41_444445_3481399/runtime_resources/working_dir_files/_ray_pkg_355028f0108691b8/model_data_nn.py", line 159, in train_fnn
    loss_function = nn.MSE
AttributeError: module 'torch.nn' has no attribute 'MSE'
2024-07-02 22:56:28,800	ERROR tune_controller.py:1331 -- Trial task failed for trial train_fnn_13ce7_00032
Traceback (most recent call last):
  File "/zfs/projects/darc/wolee_edehaan_suzienoh-exploratory-ml/kevin/venv/lib/python3.10/site-packages/ray/air/execution/_internal/event_manager.py", line 110, in resolve_future
    result = ray.get(future)
  File "/zfs/projects/darc/wolee_edehaan_suzienoh-exploratory-ml/kevin/venv/lib/python3.10/site-packages/ray/_private/auto_init_hook.py", line 21, in auto_init_wrapper
    return fn(*args, **kwargs)
  File "/zfs/projects/darc/wolee_edehaan_suzienoh-exploratory-ml/kevin/venv/lib/python3.10/site-packages/ray/_private/client_mode_hook.py", line 103, in wrapper
    return func(*args, **kwargs)
  File "/zfs/projects/darc/wolee_edehaan_suzienoh-exploratory-ml/kevin/venv/lib/python3.10/site-packages/ray/_private/worker.py", line 2613, in get
    values, debugger_breakpoint = worker.get_objects(object_refs, timeout=timeout)
  File "/zfs/projects/darc/wolee_edehaan_suzienoh-exploratory-ml/kevin/venv/lib/python3.10/site-packages/ray/_private/worker.py", line 861, in get_objects
    raise value.as_instanceof_cause()
ray.exceptions.RayTaskError(AttributeError): [36mray::ImplicitFunc.train()[39m (pid=3506082, ip=10.112.2.40, actor_id=0155b9b072db7fa94b113a9401000000, repr=train_fnn)
  File "/zfs/projects/darc/wolee_edehaan_suzienoh-exploratory-ml/kevin/venv/lib/python3.10/site-packages/ray/tune/trainable/trainable.py", line 331, in train
    raise skipped from exception_cause(skipped)
  File "/zfs/projects/darc/wolee_edehaan_suzienoh-exploratory-ml/kevin/venv/lib/python3.10/site-packages/ray/air/_internal/util.py", line 98, in run
    self._ret = self._target(*self._args, **self._kwargs)
  File "/zfs/projects/darc/wolee_edehaan_suzienoh-exploratory-ml/kevin/venv/lib/python3.10/site-packages/ray/tune/trainable/function_trainable.py", line 45, in <lambda>
    training_func=lambda: self._trainable_func(self.config),
  File "/zfs/projects/darc/wolee_edehaan_suzienoh-exploratory-ml/kevin/venv/lib/python3.10/site-packages/ray/tune/trainable/function_trainable.py", line 248, in _trainable_func
    output = fn()
  File "/zfs/projects/darc/wolee_edehaan_suzienoh-exploratory-ml/kevin/venv/lib/python3.10/site-packages/ray/tune/trainable/util.py", line 130, in inner
    return trainable(config, **fn_kwargs)
  File "/tmp/ray/session_2024-07-02_22-54-41_444445_3481399/runtime_resources/working_dir_files/_ray_pkg_355028f0108691b8/model_data_nn.py", line 159, in train_fnn
    loss_function = nn.MSE
AttributeError: module 'torch.nn' has no attribute 'MSE'
2024-07-02 22:56:31,248	ERROR tune_controller.py:1331 -- Trial task failed for trial train_fnn_13ce7_00033
Traceback (most recent call last):
  File "/zfs/projects/darc/wolee_edehaan_suzienoh-exploratory-ml/kevin/venv/lib/python3.10/site-packages/ray/air/execution/_internal/event_manager.py", line 110, in resolve_future
    result = ray.get(future)
  File "/zfs/projects/darc/wolee_edehaan_suzienoh-exploratory-ml/kevin/venv/lib/python3.10/site-packages/ray/_private/auto_init_hook.py", line 21, in auto_init_wrapper
    return fn(*args, **kwargs)
  File "/zfs/projects/darc/wolee_edehaan_suzienoh-exploratory-ml/kevin/venv/lib/python3.10/site-packages/ray/_private/client_mode_hook.py", line 103, in wrapper
    return func(*args, **kwargs)
  File "/zfs/projects/darc/wolee_edehaan_suzienoh-exploratory-ml/kevin/venv/lib/python3.10/site-packages/ray/_private/worker.py", line 2613, in get
    values, debugger_breakpoint = worker.get_objects(object_refs, timeout=timeout)
  File "/zfs/projects/darc/wolee_edehaan_suzienoh-exploratory-ml/kevin/venv/lib/python3.10/site-packages/ray/_private/worker.py", line 861, in get_objects
    raise value.as_instanceof_cause()
ray.exceptions.RayTaskError(AttributeError): [36mray::ImplicitFunc.train()[39m (pid=3506162, ip=10.112.2.40, actor_id=c2e659edcf64f8becaac7e7801000000, repr=train_fnn)
  File "/zfs/projects/darc/wolee_edehaan_suzienoh-exploratory-ml/kevin/venv/lib/python3.10/site-packages/ray/tune/trainable/trainable.py", line 331, in train
    raise skipped from exception_cause(skipped)
  File "/zfs/projects/darc/wolee_edehaan_suzienoh-exploratory-ml/kevin/venv/lib/python3.10/site-packages/ray/air/_internal/util.py", line 98, in run
    self._ret = self._target(*self._args, **self._kwargs)
  File "/zfs/projects/darc/wolee_edehaan_suzienoh-exploratory-ml/kevin/venv/lib/python3.10/site-packages/ray/tune/trainable/function_trainable.py", line 45, in <lambda>
    training_func=lambda: self._trainable_func(self.config),
  File "/zfs/projects/darc/wolee_edehaan_suzienoh-exploratory-ml/kevin/venv/lib/python3.10/site-packages/ray/tune/trainable/function_trainable.py", line 248, in _trainable_func
    output = fn()
  File "/zfs/projects/darc/wolee_edehaan_suzienoh-exploratory-ml/kevin/venv/lib/python3.10/site-packages/ray/tune/trainable/util.py", line 130, in inner
    return trainable(config, **fn_kwargs)
  File "/tmp/ray/session_2024-07-02_22-54-41_444445_3481399/runtime_resources/working_dir_files/_ray_pkg_355028f0108691b8/model_data_nn.py", line 159, in train_fnn
    loss_function = nn.MSE
AttributeError: module 'torch.nn' has no attribute 'MSE'
2024-07-02 22:56:34,196	ERROR tune_controller.py:1331 -- Trial task failed for trial train_fnn_13ce7_00034
Traceback (most recent call last):
  File "/zfs/projects/darc/wolee_edehaan_suzienoh-exploratory-ml/kevin/venv/lib/python3.10/site-packages/ray/air/execution/_internal/event_manager.py", line 110, in resolve_future
    result = ray.get(future)
  File "/zfs/projects/darc/wolee_edehaan_suzienoh-exploratory-ml/kevin/venv/lib/python3.10/site-packages/ray/_private/auto_init_hook.py", line 21, in auto_init_wrapper
    return fn(*args, **kwargs)
  File "/zfs/projects/darc/wolee_edehaan_suzienoh-exploratory-ml/kevin/venv/lib/python3.10/site-packages/ray/_private/client_mode_hook.py", line 103, in wrapper
    return func(*args, **kwargs)
  File "/zfs/projects/darc/wolee_edehaan_suzienoh-exploratory-ml/kevin/venv/lib/python3.10/site-packages/ray/_private/worker.py", line 2613, in get
    values, debugger_breakpoint = worker.get_objects(object_refs, timeout=timeout)
  File "/zfs/projects/darc/wolee_edehaan_suzienoh-exploratory-ml/kevin/venv/lib/python3.10/site-packages/ray/_private/worker.py", line 861, in get_objects
    raise value.as_instanceof_cause()
ray.exceptions.RayTaskError(AttributeError): [36mray::ImplicitFunc.train()[39m (pid=3506250, ip=10.112.2.40, actor_id=2a4c35f94093667440ee5a4701000000, repr=train_fnn)
  File "/zfs/projects/darc/wolee_edehaan_suzienoh-exploratory-ml/kevin/venv/lib/python3.10/site-packages/ray/tune/trainable/trainable.py", line 331, in train
    raise skipped from exception_cause(skipped)
  File "/zfs/projects/darc/wolee_edehaan_suzienoh-exploratory-ml/kevin/venv/lib/python3.10/site-packages/ray/air/_internal/util.py", line 98, in run
    self._ret = self._target(*self._args, **self._kwargs)
  File "/zfs/projects/darc/wolee_edehaan_suzienoh-exploratory-ml/kevin/venv/lib/python3.10/site-packages/ray/tune/trainable/function_trainable.py", line 45, in <lambda>
    training_func=lambda: self._trainable_func(self.config),
  File "/zfs/projects/darc/wolee_edehaan_suzienoh-exploratory-ml/kevin/venv/lib/python3.10/site-packages/ray/tune/trainable/function_trainable.py", line 248, in _trainable_func
    output = fn()
  File "/zfs/projects/darc/wolee_edehaan_suzienoh-exploratory-ml/kevin/venv/lib/python3.10/site-packages/ray/tune/trainable/util.py", line 130, in inner
    return trainable(config, **fn_kwargs)
  File "/tmp/ray/session_2024-07-02_22-54-41_444445_3481399/runtime_resources/working_dir_files/_ray_pkg_355028f0108691b8/model_data_nn.py", line 159, in train_fnn
    loss_function = nn.MSE
AttributeError: module 'torch.nn' has no attribute 'MSE'
2024-07-02 22:56:37,063	ERROR tune_controller.py:1331 -- Trial task failed for trial train_fnn_13ce7_00035
Traceback (most recent call last):
  File "/zfs/projects/darc/wolee_edehaan_suzienoh-exploratory-ml/kevin/venv/lib/python3.10/site-packages/ray/air/execution/_internal/event_manager.py", line 110, in resolve_future
    result = ray.get(future)
  File "/zfs/projects/darc/wolee_edehaan_suzienoh-exploratory-ml/kevin/venv/lib/python3.10/site-packages/ray/_private/auto_init_hook.py", line 21, in auto_init_wrapper
    return fn(*args, **kwargs)
  File "/zfs/projects/darc/wolee_edehaan_suzienoh-exploratory-ml/kevin/venv/lib/python3.10/site-packages/ray/_private/client_mode_hook.py", line 103, in wrapper
    return func(*args, **kwargs)
  File "/zfs/projects/darc/wolee_edehaan_suzienoh-exploratory-ml/kevin/venv/lib/python3.10/site-packages/ray/_private/worker.py", line 2613, in get
    values, debugger_breakpoint = worker.get_objects(object_refs, timeout=timeout)
  File "/zfs/projects/darc/wolee_edehaan_suzienoh-exploratory-ml/kevin/venv/lib/python3.10/site-packages/ray/_private/worker.py", line 861, in get_objects
    raise value.as_instanceof_cause()
ray.exceptions.RayTaskError(AttributeError): [36mray::ImplicitFunc.train()[39m (pid=3506332, ip=10.112.2.40, actor_id=a0487a1d871383956db5c74301000000, repr=train_fnn)
  File "/zfs/projects/darc/wolee_edehaan_suzienoh-exploratory-ml/kevin/venv/lib/python3.10/site-packages/ray/tune/trainable/trainable.py", line 331, in train
    raise skipped from exception_cause(skipped)
  File "/zfs/projects/darc/wolee_edehaan_suzienoh-exploratory-ml/kevin/venv/lib/python3.10/site-packages/ray/air/_internal/util.py", line 98, in run
    self._ret = self._target(*self._args, **self._kwargs)
  File "/zfs/projects/darc/wolee_edehaan_suzienoh-exploratory-ml/kevin/venv/lib/python3.10/site-packages/ray/tune/trainable/function_trainable.py", line 45, in <lambda>
    training_func=lambda: self._trainable_func(self.config),
  File "/zfs/projects/darc/wolee_edehaan_suzienoh-exploratory-ml/kevin/venv/lib/python3.10/site-packages/ray/tune/trainable/function_trainable.py", line 248, in _trainable_func
    output = fn()
  File "/zfs/projects/darc/wolee_edehaan_suzienoh-exploratory-ml/kevin/venv/lib/python3.10/site-packages/ray/tune/trainable/util.py", line 130, in inner
    return trainable(config, **fn_kwargs)
  File "/tmp/ray/session_2024-07-02_22-54-41_444445_3481399/runtime_resources/working_dir_files/_ray_pkg_355028f0108691b8/model_data_nn.py", line 159, in train_fnn
    loss_function = nn.MSE
AttributeError: module 'torch.nn' has no attribute 'MSE'
2024-07-02 22:56:39,481	ERROR tune_controller.py:1331 -- Trial task failed for trial train_fnn_13ce7_00036
Traceback (most recent call last):
  File "/zfs/projects/darc/wolee_edehaan_suzienoh-exploratory-ml/kevin/venv/lib/python3.10/site-packages/ray/air/execution/_internal/event_manager.py", line 110, in resolve_future
    result = ray.get(future)
  File "/zfs/projects/darc/wolee_edehaan_suzienoh-exploratory-ml/kevin/venv/lib/python3.10/site-packages/ray/_private/auto_init_hook.py", line 21, in auto_init_wrapper
    return fn(*args, **kwargs)
  File "/zfs/projects/darc/wolee_edehaan_suzienoh-exploratory-ml/kevin/venv/lib/python3.10/site-packages/ray/_private/client_mode_hook.py", line 103, in wrapper
    return func(*args, **kwargs)
  File "/zfs/projects/darc/wolee_edehaan_suzienoh-exploratory-ml/kevin/venv/lib/python3.10/site-packages/ray/_private/worker.py", line 2613, in get
    values, debugger_breakpoint = worker.get_objects(object_refs, timeout=timeout)
  File "/zfs/projects/darc/wolee_edehaan_suzienoh-exploratory-ml/kevin/venv/lib/python3.10/site-packages/ray/_private/worker.py", line 861, in get_objects
    raise value.as_instanceof_cause()
ray.exceptions.RayTaskError(AttributeError): [36mray::ImplicitFunc.train()[39m (pid=3506412, ip=10.112.2.40, actor_id=ad5e42b4339e4227f7b93c3301000000, repr=train_fnn)
  File "/zfs/projects/darc/wolee_edehaan_suzienoh-exploratory-ml/kevin/venv/lib/python3.10/site-packages/ray/tune/trainable/trainable.py", line 331, in train
    raise skipped from exception_cause(skipped)
  File "/zfs/projects/darc/wolee_edehaan_suzienoh-exploratory-ml/kevin/venv/lib/python3.10/site-packages/ray/air/_internal/util.py", line 98, in run
    self._ret = self._target(*self._args, **self._kwargs)
  File "/zfs/projects/darc/wolee_edehaan_suzienoh-exploratory-ml/kevin/venv/lib/python3.10/site-packages/ray/tune/trainable/function_trainable.py", line 45, in <lambda>
    training_func=lambda: self._trainable_func(self.config),
  File "/zfs/projects/darc/wolee_edehaan_suzienoh-exploratory-ml/kevin/venv/lib/python3.10/site-packages/ray/tune/trainable/function_trainable.py", line 248, in _trainable_func
    output = fn()
  File "/zfs/projects/darc/wolee_edehaan_suzienoh-exploratory-ml/kevin/venv/lib/python3.10/site-packages/ray/tune/trainable/util.py", line 130, in inner
    return trainable(config, **fn_kwargs)
  File "/tmp/ray/session_2024-07-02_22-54-41_444445_3481399/runtime_resources/working_dir_files/_ray_pkg_355028f0108691b8/model_data_nn.py", line 159, in train_fnn
    loss_function = nn.MSE
AttributeError: module 'torch.nn' has no attribute 'MSE'
2024-07-02 22:56:43,524	ERROR tune_controller.py:1331 -- Trial task failed for trial train_fnn_13ce7_00037
Traceback (most recent call last):
  File "/zfs/projects/darc/wolee_edehaan_suzienoh-exploratory-ml/kevin/venv/lib/python3.10/site-packages/ray/air/execution/_internal/event_manager.py", line 110, in resolve_future
    result = ray.get(future)
  File "/zfs/projects/darc/wolee_edehaan_suzienoh-exploratory-ml/kevin/venv/lib/python3.10/site-packages/ray/_private/auto_init_hook.py", line 21, in auto_init_wrapper
    return fn(*args, **kwargs)
  File "/zfs/projects/darc/wolee_edehaan_suzienoh-exploratory-ml/kevin/venv/lib/python3.10/site-packages/ray/_private/client_mode_hook.py", line 103, in wrapper
    return func(*args, **kwargs)
  File "/zfs/projects/darc/wolee_edehaan_suzienoh-exploratory-ml/kevin/venv/lib/python3.10/site-packages/ray/_private/worker.py", line 2613, in get
    values, debugger_breakpoint = worker.get_objects(object_refs, timeout=timeout)
  File "/zfs/projects/darc/wolee_edehaan_suzienoh-exploratory-ml/kevin/venv/lib/python3.10/site-packages/ray/_private/worker.py", line 861, in get_objects
    raise value.as_instanceof_cause()
ray.exceptions.RayTaskError(AttributeError): [36mray::ImplicitFunc.train()[39m (pid=3506493, ip=10.112.2.40, actor_id=8c17a4bd92f28fa837e63ff301000000, repr=train_fnn)
  File "/zfs/projects/darc/wolee_edehaan_suzienoh-exploratory-ml/kevin/venv/lib/python3.10/site-packages/ray/tune/trainable/trainable.py", line 331, in train
    raise skipped from exception_cause(skipped)
  File "/zfs/projects/darc/wolee_edehaan_suzienoh-exploratory-ml/kevin/venv/lib/python3.10/site-packages/ray/air/_internal/util.py", line 98, in run
    self._ret = self._target(*self._args, **self._kwargs)
  File "/zfs/projects/darc/wolee_edehaan_suzienoh-exploratory-ml/kevin/venv/lib/python3.10/site-packages/ray/tune/trainable/function_trainable.py", line 45, in <lambda>
    training_func=lambda: self._trainable_func(self.config),
  File "/zfs/projects/darc/wolee_edehaan_suzienoh-exploratory-ml/kevin/venv/lib/python3.10/site-packages/ray/tune/trainable/function_trainable.py", line 248, in _trainable_func
    output = fn()
  File "/zfs/projects/darc/wolee_edehaan_suzienoh-exploratory-ml/kevin/venv/lib/python3.10/site-packages/ray/tune/trainable/util.py", line 130, in inner
    return trainable(config, **fn_kwargs)
  File "/tmp/ray/session_2024-07-02_22-54-41_444445_3481399/runtime_resources/working_dir_files/_ray_pkg_355028f0108691b8/model_data_nn.py", line 159, in train_fnn
    loss_function = nn.MSE
AttributeError: module 'torch.nn' has no attribute 'MSE'
